<?xml version="1.0" encoding="utf-8"?>
<!-- This URDF was automatically created by SolidWorks to URDF Exporter! Originally created by Stephen Brawner (brawner@gmail.com) 
     Commit Version: 1.6.0-1-g15f4949  Build Version: 1.6.7594.29634
     For more information, please see http://wiki.ros.org/sw_urdf_exporter -->
<robot
  name="v5"
  xmlns:xacro="http://ros.org/wiki/xacro">

  <!-- Included URDF Files -->
  <xacro:include filename="$(find segbot_description)/urdf/segway_110_base.urdf.xacro" />


  <link
    name="base_link">
    <inertial>
      <origin
        xyz="0.211886378 -0.81046675318 0.51736994677"
        rpy="-1.57 0 0" />
      <mass
        value="20.4660866954057" />
      <inertia
        ixx="0.193568038684775"
        ixy="0.00548623614276343"
        ixz="-6.15228083843436E-05"
        iyy="0.108859012808764"
        iyz="-0.00384844545395753"
        izz="0.229327239703698" />
    </inertial>
    <visual>
      <origin
        xyz="0.211886378 -0.81046675318 0.51736994677"
        rpy="-1.57 0 0" />
      <geometry>
        <mesh
          filename="package://v5_asm/meshes/base_link.dae" scale = "0.0254 0.0254 0.0254"/>
      </geometry>
      <material
        name="">
        <color
          rgba="0.752941176470588 0.752941176470588 0.752941176470588 1" />
      </material>
    </visual>
    <collision>
      <origin
        xyz="0.211886378 -0.81046675318 0.51736994677"
        rpy="-1.57 0 0" />
      <geometry>
        <mesh
          filename="package://v5_asm/meshes/base_link.dae" scale = "0.0254 0.0254 0.0254"/>
      </geometry>
    </collision>
  </link>

    <!-- Add the segway base -->
  <xacro:segway_110_base  name="segway_base" parent="base_link">
    <origin xyz="0.000679400372348427 0.00391721605940215 0.0567343349671494}" rpy="0 0 0" />
  </xacro:segway_110_base>


  <!-- <link
    name="caster_plate">
    <inertial>
      <origin
        xyz="0.000679400372348427 0.00391721605940215 0.0567343349671494"
        rpy="0 0 0" />
      <mass
        value="2.27313334797282" />
      <inertia
        ixx="0.0136917281986426"
        ixy="2.03686560822833E-11"
        ixz="1.76700033879541E-10"
        iyy="0.0419319216248708"
        iyz="4.67976965217184E-11"
        izz="0.0282979087198513" />
    </inertial>
    <visual>
      <origin
        xyz="0 0 0"
        rpy="0 0 0" />
      <geometry>
        <mesh
          filename="package://v5_asm/meshes/caster_plate.dae" />
      </geometry>
      <material
        name="">
        <color
          rgba="0.792156862745098 0.819607843137255 0.933333333333333 1" />
      </material>
    </visual>
    <collision>
      <origin
        xyz="0 0 0"
        rpy="0 0 0" />
      <geometry>
        <mesh
          filename="package://v5_asm/meshes/caster_plate.dae" />
      </geometry>
    </collision>
  </link>

  <joint
    name="caster_plate"
    type="fixed">
    <origin
      xyz="0.23172 -0.73293 0.45052"
      rpy="1.5708 0 0" />
    <parent
      link="base_link" />
    <child
      link="caster_plate" />
    <axis
      xyz="0 0 0" />
  </joint>


  <link
    name="front_caster_bracket">
    <inertial>
      <origin
        xyz="0.365335288180011 0.248678222225418 0.0691082920818489"
        rpy="0 0 0" />
      <mass
        value="0.0568106650345589" />
      <inertia
        ixx="8.23477905821372E-05"
        ixy="1.16897757599192E-09"
        ixz="1.34346506178931E-05"
        iyy="6.30736438277275E-05"
        iyz="8.37968542847457E-11"
        izz="6.04054945077207E-05" />
    </inertial>
    <visual>
      <origin
        xyz="0 0 0"
        rpy="0 0 0" />
      <geometry>
        <mesh
          filename="package://v5_asm/meshes/back_caster_bracket.dae" scale = "0.001 0.001 0.001"/>
      </geometry>
      <material
        name="">
        <color
          rgba="0.752941176470588 0.752941176470588 0.752941176470588 1" />
      </material>
    </visual>
    <collision>
      <origin
        xyz="0 0 0"
        rpy="0 0 0" />
      <geometry>
        <mesh
          filename="package://v5_asm/meshes/back_caster_bracket.dae" scale = "0.001 0.001 0.001"/>
      </geometry>
    </collision>
  </link>
  <joint
    name="front_caster_bracket"
    type="fixed">
    <origin
      xyz="-0.2477 -0.02493 0.75732"
      rpy="1.5708 1.5708 0" />
    <parent
      link="caster_plate" />
    <child
      link="front_caster_bracket" />
    <axis
      xyz="0 0 0" />
  </joint>


  <link
    name="front_caster_wheel">
    <inertial>
      <origin
        xyz="0 -1.11022302462516E-16 -5.55111512312578E-17"
        rpy="0 0 0" />
      <mass
        value="0.536233974367649" />
      <inertia
        ixx="0.00102083888487686"
        ixy="-3.7578670947432E-11"
        ixz="-5.49056044341157E-18"
        iyy="0.00186916214511589"
        iyz="4.86077078101959E-19"
        izz="0.0010208060948475" />
    </inertial>
    <visual>
      <origin
        xyz="0 0 0"
        rpy="0 0 0" />
      <geometry>
        <mesh
          filename="package://v5_asm/meshes/front_caster_wheel.dae" />
      </geometry>
      <material
        name="">
        <color
          rgba="1 1 1 1" />
      </material>
    </visual>
    <collision>
      <origin
        xyz="0 0 0"
        rpy="0 0 0" />
      <geometry>
        <mesh
          filename="package://v5_asm/meshes/front_caster_wheel.dae" />
      </geometry>
    </collision>
  </link>
  <joint
    name="front_caster_wheel"
    type="continuous">
    <origin
      xyz="0.35417 0.24809 0.11425"
      rpy="0 0 0" />
    <parent
      link="front_caster_bracket" />
    <child
      link="front_caster_wheel" />
    <axis
      xyz="0 0 0" />
  </joint>


  <link
    name="back_caster_bracket">
    <inertial>
      <origin
        xyz="1.67037157439154E-07 -0.0868275208414239 0.00764135388193965"
        rpy="0 0 0" />
      <mass
        value="0.0423689978722741" />
      <inertia
        ixx="6.26126883817095E-05"
        ixy="-8.45844635296862E-10"
        ixz="2.25772431514382E-10"
        iyy="7.35721776271657E-05"
        iyz="-1.3433956339157E-05"
        izz="5.16282462873607E-05" />
    </inertial>
    <visual>
      <origin
        xyz="0 0 0"
        rpy="0 0 0" />
      <geometry>
        <mesh
          filename="package://v5_asm/meshes/back_caster_bracket.dae" scale = "0.001 0.001 0.001"/>
      </geometry>
      <material
        name="">
        <color
          rgba="0.792156862745098 0.819607843137255 0.933333333333333 1" />
      </material>
    </visual>
    <collision>
      <origin
        xyz="0 0 0"
        rpy="0 0 0" />
      <geometry>
        <mesh
          filename="package://v5_asm/meshes/back_caster_bracket.dae" scale = "0.001 0.001 0.001"/>
      </geometry>
    </collision>
  </link>
  <joint
    name="back_caster_bracket"
    type="fixed">
    <origin
      xyz="-0.00094312 -0.06237 -0.16395"
      rpy="1.5708 0.037075 0" />
    <parent
      link="caster_plate" />
    <child
      link="back_caster_bracket" />
    <axis
      xyz="0 0 0" />
  </joint>


  <link
    name="back_caster_wheel">
    <inertial>
      <origin
        xyz="-1.0456E-11 6.7448E-11 -1.9645E-13"
        rpy="0 0 0" />
      <mass
        value="0.53622" />
      <inertia
        ixx="0.0010208"
        ixy="-3.7579E-11"
        ixz="-7.6578E-13"
        iyy="0.0018692"
        iyz="7.6476E-19"
        izz="0.0010208" />
    </inertial>
    <visual>
      <origin
        xyz="0 0 0"
        rpy="0 0 0" />
      <geometry>
        <mesh
          filename="package://v5_asm/meshes/back_caster_wheel.dae" />
      </geometry>
      <material
        name="">
        <color
          rgba="1 1 1 1" />
      </material>
    </visual>
    <collision>
      <origin
        xyz="0 0 0"
        rpy="0 0 0" />
      <geometry>
        <mesh
          filename="package://v5_asm/meshes/back_caster_wheel.dae" />
      </geometry>
    </collision>
  </link>
  <joint
    name="back_caster_wheel"
    type="continuous">
    <origin
      xyz="-0.00022561 -0.071859 0.068169"
      rpy="3.1416 -0.044138 1.5708" />
    <parent
      link="back_caster_bracket" />
    <child
      link="back_caster_wheel" />
    <axis
      xyz="0 0 0" />
  </joint>


  <link
    name="left_gear_box">
    <inertial>
      <origin
        xyz="0.00739304791093054 0.0184132537576796 -0.00195305339886431"
        rpy="0 0 0" />
      <mass
        value="1.63780560174486" />
      <inertia
        ixx="0.00495644861508239"
        ixy="-0.000669333725659883"
        ixz="6.71187797682122E-05"
        iyy="0.00382306425706198"
        iyz="0.000163933699935291"
        izz="0.00760016402666202" />
    </inertial>
    <visual>
      <origin
        xyz="0 0 0"
        rpy="0 0 0" />
      <geometry>
        <mesh
          filename="package://v5_asm/meshes/left_gear_box.dae" />
      </geometry>
      <material
        name="">
        <color
          rgba="0.792156862745098 0.819607843137255 0.933333333333333 1" />
      </material>
    </visual>
    <collision>
      <origin
        xyz="0 0 0"
        rpy="0 0 0" />
      <geometry>
        <mesh
          filename="package://v5_asm/meshes/left_gear_box.dae" />
      </geometry>
    </collision>
  </link>
  <joint
    name="left_gear_box"
    type="fixed">
    <origin
      xyz="0.44635 -0.78338 0.47561"
      rpy="-1.5708 0 -1.5708" />
    <parent
      link="base_link" />
    <child
      link="left_gear_box" />
    <axis
      xyz="0 0 0" />
  </joint>


  <link
    name="left_i_wheel">
    <inertial>
      <origin
        xyz="0.0177417489006745 -4.1929935734597E-07 -1.59892757811697E-07"
        rpy="0 1.57079632679 0" />
      <mass
        value="10.8391746130566" />
      <inertia
        ixx="0.359971317777513"
        ixy="-1.74908672611907E-08"
        ixz="-1.43629913581696E-07"
        iyy="0.18578129227598"
        iyz="-1.44805236117901E-06"
        izz="0.185820148109984" />
    </inertial>
    <visual>
      <origin
        xyz="0 0 0"
        rpy="0 1.57079632679 0" />
      <geometry>
        <mesh
          filename="package://v5_asm/meshes/left_i_wheel.dae" scale="0.001 0.001 0.001"/>
      </geometry>
      <material
        name="">
        <color
          rgba="0.752941176470588 0.752941176470588 0.752941176470588 1" />
      </material>
    </visual>
    <collision>
      <origin
        xyz="0 0 0"
        rpy="0 1.57079632679 0" />
      <geometry>
        <mesh
          filename="package://v5_asm/meshes/left_i_wheel.dae" scale="0.001 0.001 0.001"/>
      </geometry>
    </collision>
  </link>
  <joint
    name="left_i_wheel"
    type="continuous">
    <origin
      xyz="0 0 0.052156"
      rpy="1.1682 1.5708 0" />
    <parent
      link="left_gear_box" />
    <child
      link="left_i_wheel" />
    <axis
      xyz="0 0 0" />
  </joint>


  <link
    name="right_gear_box">
    <inertial>
      <origin
        xyz="0.00739304791093043 -0.0184132537576797 0.00195305339886435"
        rpy="0 0 0" />
      <mass
        value="1.63780560174486" />
      <inertia
        ixx="0.00495644861508239"
        ixy="0.000669333725659883"
        ixz="-6.71187797682128E-05"
        iyy="0.00382306425706198"
        iyz="0.00016393369993529"
        izz="0.00760016402666201" />
    </inertial>
    <visual>
      <origin
        xyz="0 0 0"
        rpy="0 0 0" />
      <geometry>
        <mesh
          filename="package://v5_asm/meshes/right_gear_box.dae" />
      </geometry>
      <material
        name="">
        <color
          rgba="0.792156862745098 0.819607843137255 0.933333333333333 1" />
      </material>
    </visual>
    <collision>
      <origin
        xyz="0 0 0"
        rpy="0 0 0" />
      <geometry>
        <mesh
          filename="package://v5_asm/meshes/right_gear_box.dae" />
      </geometry>
    </collision>
  </link>
  <joint
    name="right_gear_box"
    type="fixed">
    <origin
      xyz="0.018326 -0.78338 0.47561"
      rpy="1.5708 0 1.5708" />
    <parent
      link="base_link" />
    <child
      link="right_gear_box" />
    <axis
      xyz="0 0 0" />
  </joint>


  <link
    name="right_i_wheel">
    <inertial>
      <origin
        xyz="0.0177417489006745 -4.19294752806998E-07 -1.59891818396485E-07"
        rpy="0 1.57079632679 0" />
      <mass
        value="10.8391746130566" />
      <inertia
        ixx="0.359969793874044"
        ixy="-8.40262466952751E-09"
        ixz="2.00445994282709E-08"
        iyy="0.185780931677524"
        iyz="-1.19702130537763E-06"
        izz="0.185818951022821" />
    </inertial>
    <visual>
      <origin
        xyz="0 0 0"
        rpy="0 1.57079632679 0" />
      <geometry>
        <mesh
          filename="package://v5_asm/meshes/right_i_wheel.dae" scale="0.001 0.001 0.001"/>
      </geometry>
      <material
        name="">
        <color
          rgba="0.752941176470588 0.752941176470588 0.752941176470588 1" />
      </material>
    </visual>
    <collision>
      <origin
        xyz="0 0 0"
        rpy="0 1.57079632679 0" />
      <geometry>
        <mesh
          filename="package://v5_asm/meshes/right_i_wheel.dae" scale="0.001 0.001 0.001"/>
      </geometry>
    </collision>
  </link>
  <joint
    name="right_i_wheel"
    type="continuous">
    <origin
      xyz="0 0 -0.052156"
      rpy="1.5708 -1.5708 0" />
    <parent
      link="right_gear_box" />
    <child
      link="right_i_wheel" />
    <axis
      xyz="0 0 0" />
  </joint> -->


  <link
    name="lower_chasis_and_battery">
    <inertial>
      <origin
        xyz="-7.40624126181477E-05 0.0616565980495644 -0.0313255964907295"
        rpy="0 0 0" />
      <mass
        value="14.0902746517906" />
      <inertia
        ixx="0.0787989259767557"
        ixy="-1.28686109765554E-06"
        ixz="8.31096809270812E-05"
        iyy="0.208127955865328"
        iyz="-0.00143169842059501"
        izz="0.144911480468362" />
    </inertial>
    <visual>
      <origin
        xyz="0 0 0"
        rpy="0 0 0" />
      <geometry>
        <mesh
          filename="package://v5_asm/meshes/lower_chasis_and_battery.dae" />
      </geometry>
      <material
        name="">
        <color
          rgba="0.298039215686275 0.298039215686275 0.298039215686275 1" />
      </material>
    </visual>
    <collision>
      <origin
        xyz="0 0 0"
        rpy="0 0 0" />
      <geometry>
        <mesh
          filename="package://v5_asm/meshes/lower_chasis_and_battery.dae" />
      </geometry>
    </collision>
  </link>
  <joint
    name="lower_chasis_and_battery"
    type="fixed">
    <origin
      xyz="0.23234 -0.82239 0.33073"
      rpy="1.5708 0 0" />
    <parent
      link="base_link" />
    <child
      link="lower_chasis_and_battery" />
    <axis
      xyz="0 0 0" />
  </joint>


  <link
    name="upper_chasis">
    <inertial>
      <origin
        xyz="0.408010034067037 0.523436425874833 0.310459511796759"
        rpy="0 0 0" />
      <mass
        value="0.830786236359305" />
      <inertia
        ixx="0.0113561959346229"
        ixy="-1.77137015581408E-06"
        ixz="-1.92392161060582E-12"
        iyy="0.00307752453202283"
        iyz="-2.16245929932274E-11"
        izz="0.00841950781307632" />
    </inertial>
    <visual>
      <origin
        xyz="0 0 0"
        rpy="0 0 0" />
      <geometry>
        <mesh
          filename="package://v5_asm/meshes/upper_chasis.dae" />
      </geometry>
      <material
        name="">
        <color
          rgba="0.792156862745098 0.819607843137255 0.933333333333333 1" />
      </material>
    </visual>
    <collision>
      <origin
        xyz="0 0 0"
        rpy="0 0 0" />
      <geometry>
        <mesh
          filename="package://v5_asm/meshes/upper_chasis.dae" />
      </geometry>
    </collision>
  </link>
  <joint
    name="upper_chasis"
    type="fixed">
    <origin
      xyz="-0.07828 -0.90265 0.78248"
      rpy="1.5708 0 1.5708" />
    <parent
      link="base_link" />
    <child
      link="upper_chasis" />
    <axis
      xyz="0 0 0" />
  </joint>


  <link
    name="kinect">
    <inertial>
      <origin
        xyz="2.85546254141789E-06 0.00442617876381557 -0.0296652165432638"
        rpy="0 0 0" />
      <mass
        value="2.43875456249446" />
      <inertia
        ixx="0.00366777685200428"
        ixy="3.65666914100067E-08"
        ixz="-4.13408382742863E-07"
        iyy="0.0053508686708892"
        iyz="0.000216031980389351"
        izz="0.00205613161528836" />
    </inertial>
    <visual>
      <origin
        xyz="0 0 0"
        rpy="0 0 0" />
      <geometry>
        <mesh
          filename="package://v5_asm/meshes/kinect.dae" />
      </geometry>
      <material
        name="">
        <color
          rgba="0.941176470588235 0.941176470588235 0.941176470588235 1" />
      </material>
    </visual>
    <collision>
      <origin
        xyz="0 0 0"
        rpy="0 0 0" />
      <geometry>
        <mesh
          filename="package://v5_asm/meshes/kinect.dae" />
      </geometry>
    </collision>
  </link>
  <joint
    name="kinect"
    type="fixed">
    <origin
      xyz="0.33702 0.80334 0.31779"
      rpy="3.1416 -1.5708 0" />
    <parent
      link="upper_chasis" />
    <child
      link="kinect" />
    <axis
      xyz="0 0 0" />
  </joint>


  <link
    name="lidar">
    <inertial>
      <origin
        xyz="0.000294783332731696 0.0357745252112349 -2.58234201516716E-06"
        rpy="0 0 0" />
      <mass
        value="0.585082164914895" />
      <inertia
        ixx="0.00062906696678346"
        ixy="-6.8476888066688E-08"
        ixz="-1.14106053435051E-10"
        iyy="0.000749251783736662"
        iyz="-5.004876230364E-08"
        izz="0.000630263932043022" />
    </inertial>
    <visual>
      <origin
        xyz="0 0 0"
        rpy="0 0 0" />
      <geometry>
        <mesh
          filename="package://v5_asm/meshes/lidar.dae" />
      </geometry>
      <material
        name="">
        <color
          rgba="0.792156862745098 0.819607843137255 0.933333333333333 1" />
      </material>
    </visual>
    <collision>
      <origin
        xyz="0 0 0"
        rpy="0 0 0" />
      <geometry>
        <mesh
          filename="package://v5_asm/meshes/lidar.dae" />
      </geometry>
    </collision>
  </link>
  <joint
    name="lidar"
    type="fixed">
    <origin
      xyz="0.40469 0.76764 0.30488"
      rpy="3.1416 0 0.087266" />
    <parent
      link="upper_chasis" />
    <child
      link="lidar" />
    <axis
      xyz="0 0 0" />
  </joint>


  <link
    name="monitor">
    <inertial>
      <origin
        xyz="-9.44272438019311E-13 0.0100274135784167 1.28586030712086E-12"
        rpy="0 0 0" />
      <mass
        value="1.77239075139848" />
      <inertia
        ixx="0.0081743729118215"
        ixy="-2.82200542311203E-12"
        ixz="4.5362584792376E-17"
        iyy="0.0290517648183889"
        iyz="-6.23620652586998E-17"
        izz="0.0209962115185463" />
    </inertial>
    <visual>
      <origin
        xyz="0 0 0"
        rpy="0 0 0" />
      <geometry>
        <mesh
          filename="package://v5_asm/meshes/monitor.dae" />
      </geometry>
      <material
        name="">
        <color
          rgba="0.647058823529412 0.619607843137255 0.6 1" />
      </material>
    </visual>
    <collision>
      <origin
        xyz="0 0 0"
        rpy="0 0 0" />
      <geometry>
        <mesh
          filename="package://v5_asm/meshes/monitor.dae" />
      </geometry>
    </collision>
  </link>
  <joint
    name="monitor"
    type="fixed">
    <origin
      xyz="0.4177 0.55518 0.3106"
      rpy="1.5708 1.5708 0" />
    <parent
      link="upper_chasis" />
    <child
      link="monitor" />
    <axis
      xyz="0 0 0" />
  </joint>


  <link
    name="arm_stand">
    <inertial>
      <origin
        xyz="-0.0449002179804069 -0.00120158576170751 -0.0786427433397576"
        rpy="0 0 0" />
      <mass
        value="1.50525286307822" />
      <inertia
        ixx="0.00548888032967621"
        ixy="1.929980925743E-05"
        ixz="-0.00180882087465193"
        iyy="0.00662090700121496"
        iyz="6.80641116194522E-06"
        izz="0.00455713436329697" />
    </inertial>
    <visual>
      <origin
        xyz="0 0 0"
        rpy="0 0 0" />
      <geometry>
        <mesh
          filename="package://v5_asm/meshes/arm_stand.dae" />
      </geometry>
      <material
        name="">
        <color
          rgba="0.792156862745098 0.819607843137255 0.933333333333333 1" />
      </material>
    </visual>
    <collision>
      <origin
        xyz="0 0 0"
        rpy="0 0 0" />
      <geometry>
        <mesh
          filename="package://v5_asm/meshes/arm_stand.dae" />
      </geometry>
    </collision>
  </link>
  <joint
    name="arm_stand"
    type="fixed">
    <origin
      xyz="0.17434 -0.98064 0.86287"
      rpy="0 -0.5236 1.5708" />
    <parent
      link="base_link" />
    <child
      link="arm_stand" />
    <axis
      xyz="0.5 0 0.86603" />
  </joint>


  <link
    name="ur5_joint_1">
    <inertial>
      <origin
        xyz="-0.0851578863895917 0.0164402270227318 -6.18585645567604E-06"
        rpy="0 0 0" />
      <mass
        value="1.57303506561777" />
      <inertia
        ixx="0.00282985739222354"
        ixy="0.000319345479228156"
        ixz="-1.3467674434334E-07"
        iyy="0.00253797666126007"
        iyz="4.48202109511723E-07"
        izz="0.00262077848273317" />
    </inertial>
    <visual>
      <origin
        xyz="0 0 0"
        rpy="0 0 0" />
      <geometry>
        <mesh
          filename="package://v5_asm/meshes/ur5_joint_1.dae" />
      </geometry>
      <material
        name="">
        <color
          rgba="0.752941176470588 0.752941176470588 0.752941176470588 1" />
      </material>
    </visual>
    <collision>
      <origin
        xyz="0 0 0"
        rpy="0 0 0" />
      <geometry>
        <mesh
          filename="package://v5_asm/meshes/ur5_joint_1.dae" />
      </geometry>
    </collision>
  </link>
  <joint
    name="ur5_joint_1"
    type="continuous">
    <origin
      xyz="0 0 0.016"
      rpy="3.0957 1.5708 0" />
    <parent
      link="arm_stand" />
    <child
      link="ur5_joint_1" />
    <axis
      xyz="0.86603 -0.022933 0.49947" />
  </joint>


  <link
    name="ur5_joint_2">
    <inertial>
      <origin
        xyz="-0.302716727855682 0.132315664181211 1.77064524820025E-07"
        rpy="0 0 0" />
      <mass
        value="4.66880321169942" />
      <inertia
        ixx="0.00636704093991199"
        ixy="-6.20745954096023E-13"
        ixz="8.93482687230754E-07"
        iyy="0.0218238021315899"
        iyz="-2.20693710821339E-07"
        izz="0.0213266819330185" />
    </inertial>
    <visual>
      <origin
        xyz="0 0 0"
        rpy="0 0 0" />
      <geometry>
        <mesh
          filename="package://v5_asm/meshes/ur5_joint_2.dae" />
      </geometry>
      <material
        name="">
        <color
          rgba="0.752941176470588 0.752941176470588 0.752941176470588 1" />
      </material>
    </visual>
    <collision>
      <origin
        xyz="0 0 0"
        rpy="0 0 0" />
      <geometry>
        <mesh
          filename="package://v5_asm/meshes/ur5_joint_2.dae" />
      </geometry>
    </collision>
  </link>
  <joint
    name="ur5_joint_2"
    type="continuous">
    <origin
      xyz="-0.090744 0.0008 0.08608"
      rpy="-3.1416 -1.5181 -3.1416" />
    <parent
      link="ur5_joint_1" />
    <child
      link="ur5_joint_2" />
    <axis
      xyz="0.45313 -0.022933 -0.89115" />
  </joint>


  <link
    name="ur5_joint_3">
    <inertial>
      <origin
        xyz="-0.685100751897905 0.0209736677965809 -2.59227660004413E-06"
        rpy="0 0 0" />
      <mass
        value="2.68543515548644" />
      <inertia
        ixx="0.00224100169880811"
        ixy="-0.000112853566886677"
        ixz="4.22489066080091E-07"
        iyy="0.0118077394225818"
        iyz="-2.6931174116473E-07"
        izz="0.0116551789315217" />
    </inertial>
    <visual>
      <origin
        xyz="0 0 0"
        rpy="0 0 0" />
      <geometry>
        <mesh
          filename="package://v5_asm/meshes/ur5_joint_3.dae" />
      </geometry>
      <material
        name="">
        <color
          rgba="0.752941176470588 0.752941176470588 0.752941176470588 1" />
      </material>
    </visual>
    <collision>
      <origin
        xyz="0 0 0"
        rpy="0 0 0" />
      <geometry>
        <mesh
          filename="package://v5_asm/meshes/ur5_joint_3.dae" />
      </geometry>
    </collision>
  </link>
  <joint
    name="ur5_joint_3"
    type="continuous">
    <origin
      xyz="-1.0036 -0.001 -0.13737"
      rpy="3.1416 0.27205 3.1416" />
    <parent
      link="ur5_joint_2" />
    <child
      link="ur5_joint_3" />
    <axis
      xyz="0.197 0.022933 -0.98013" />
  </joint>


  <link
    name="ur5_joint_4">
    <inertial>
      <origin
        xyz="-0.899697047068307 0.0988302133788646 1.25831148872768E-05"
        rpy="0 0 0" />
      <mass
        value="0.540829880777314" />
      <inertia
        ixx="0.000411405743799164"
        ixy="4.27843749306121E-05"
        ixz="-2.86034926684405E-07"
        iyy="0.000367441022672126"
        iyz="4.08936833204405E-07"
        izz="0.000386999743676486" />
    </inertial>
    <visual>
      <origin
        xyz="0 0 0"
        rpy="0 0 0" />
      <geometry>
        <mesh
          filename="package://v5_asm/meshes/ur5_joint_4.dae" />
      </geometry>
      <material
        name="">
        <color
          rgba="0.752941176470588 0.752941176470588 0.752941176470588 1" />
      </material>
    </visual>
    <collision>
      <origin
        xyz="0 0 0"
        rpy="0 0 0" />
      <geometry>
        <mesh
          filename="package://v5_asm/meshes/ur5_joint_4.dae" />
      </geometry>
    </collision>
  </link>
  <joint
    name="ur5_joint_4"
    type="continuous">
    <origin
      xyz="-0.73966 0.00017001 0.88848"
      rpy="0 -1.3885 0" />
    <parent
      link="ur5_joint_3" />
    <child
      link="ur5_joint_4" />
    <axis
      xyz="0.92818 -0.022933 0.37143" />
  </joint>


  <link
    name="ur5_joint_5">
    <inertial>
      <origin
        xyz="-0.987029196187412 0.106246301157145 -1.16733060833152E-05"
        rpy="0 0 0" />
      <mass
        value="0.540828690385584" />
      <inertia
        ixx="0.000367439487831712"
        ixy="4.27816506557871E-05"
        ixz="4.10392907377143E-07"
        iyy="0.00041140340411158"
        iyz="-2.86656455584028E-07"
        izz="0.000387001350926616" />
    </inertial>
    <visual>
      <origin
        xyz="0 0 0"
        rpy="0 0 0" />
      <geometry>
        <mesh
          filename="package://v5_asm/meshes/ur5_joint_5.dae" />
      </geometry>
      <material
        name="">
        <color
          rgba="0.752941176470588 0.752941176470588 0.752941176470588 1" />
      </material>
    </visual>
    <collision>
      <origin
        xyz="0 0 0"
        rpy="0 0 0" />
      <geometry>
        <mesh
          filename="package://v5_asm/meshes/ur5_joint_5.dae" />
      </geometry>
    </collision>
  </link>
  <joint
    name="ur5_joint_5"
    type="continuous">
    <origin
      xyz="-0.00017 0.15975 0.098107"
      rpy="-2.0401 0 0" />
    <parent
      link="ur5_joint_4" />
    <child
      link="ur5_joint_5" />
    <axis
      xyz="0.92818 -0.3209 -0.18844" />
  </joint>


  <link
    name="ur5_joint_6">
    <inertial>
      <origin
        xyz="-0.99827785140301 0.169556144936086 0.000119070736525395"
        rpy="0 0 0" />
      <mass
        value="0.164823443517059" />
      <inertia
        ixx="6.82697161636503E-05"
        ixy="5.77535127595612E-08"
        ixz="-3.20008189989337E-07"
        iyy="0.000116042885181722"
        iyz="-8.84003773573597E-08"
        izz="6.85506707041207E-05" />
    </inertial>
    <visual>
      <origin
        xyz="0 0 0"
        rpy="0 0 0" />
      <geometry>
        <mesh
          filename="package://v5_asm/meshes/ur5_joint_6.dae" />
      </geometry>
      <material
        name="">
        <color
          rgba="0.752941176470588 0.752941176470588 0.752941176470588 1" />
      </material>
    </visual>
    <collision>
      <origin
        xyz="0 0 0"
        rpy="0 0 0" />
      <geometry>
        <mesh
          filename="package://v5_asm/meshes/ur5_joint_6.dae" />
      </geometry>
    </collision>
  </link>
  <joint
    name="ur5_joint_6"
    type="continuous">
    <origin
      xyz="-1.873 0.00017 0.48083"
      rpy="-3.1416 -0.50259 -3.1416" />
    <parent
      link="ur5_joint_5" />
    <child
      link="ur5_joint_6" />
    <axis
      xyz="0.90417 0.3209 0.28196" />
  </joint>


  <link
    name="2F140">
    <inertial>
      <origin
        xyz="0.000236918070499081 0.0555066732025124 0.21132090098005"
        rpy="0 0 0" />
      <mass
        value="0.354648189700146" />
      <inertia
        ixx="0.000236348903219918"
        ixy="9.7527968895236E-08"
        ixz="-1.13038416546566E-08"
        iyy="0.000167617300695711"
        iyz="-1.12506157298886E-07"
        izz="0.000275420455724526" />
    </inertial>
    <visual>
      <origin
        xyz="0 0 0"
        rpy="0 0 0" />
      <geometry>
        <mesh
          filename="package://v5_asm/meshes/2F140.dae" />
      </geometry>
      <material
        name="">
        <color
          rgba="0.752941176470588 0.752941176470588 0.752941176470588 1" />
      </material>
    </visual>
    <collision>
      <origin
        xyz="0 0 0"
        rpy="0 0 0" />
      <geometry>
        <mesh
          filename="package://v5_asm/meshes/2F140.dae" />
      </geometry>
    </collision>
  </link>
  <joint
    name="2F140"
    type="continuous">
    <origin
      xyz="-0.79422 0.19124 0.055252"
      rpy="-3.1416 -1.3049 -3.1416" />
    <parent
      link="ur5_joint_6" />
    <child
      link="2F140" />
    <axis
      xyz="0.034479 0.3209 -0.94649" />
  </joint>

  
</robot>