<?xml version="1.0" encoding="utf-8" ?>
<!-- =================================================================================== -->
<!-- |    This document was autogenerated by xacro from /home/fri/catkin_ws_bwi/src/segbot/v5_asm/urdf/ur5_joint_limited_robot.urdf.xacro | -->
<!-- |    EDITING THIS FILE BY HAND IS NOT RECOMMENDED                                 | -->
<!-- =================================================================================== -->
<robot name="ur5">
    <link name="world" />
    <gazebo>
        <plugin filename="libgazebo_ros_control.so" name="ros_control">
            <!--robotNamespace>/</robotNamespace-->
            <!--robotSimType>gazebo_ros_control/DefaultRobotHWSim</robotSimType-->
        </plugin>
        <!--
    <plugin name="gazebo_ros_power_monitor_controller" filename="libgazebo_ros_power_monitor.so">
      <alwaysOn>true</alwaysOn>
      <updateRate>1.0</updateRate>
      <timeout>5</timeout>
      <powerStateTopic>power_state</powerStateTopic>
      <powerStateRate>10.0</powerStateRate>
      <fullChargeCapacity>87.78</fullChargeCapacity>     
      <dischargeRate>-474</dischargeRate>
      <chargeRate>525</chargeRate>
      <dischargeVoltage>15.52</dischargeVoltage>
      <chargeVoltage>16.41</chargeVoltage>
    </plugin>
-->
    </gazebo>
    <!-- measured from model -->
    <!--property name="shoulder_height" value="0.089159" /-->
    <!--property name="shoulder_offset" value="0.13585" /-->
    <!-- shoulder_offset - elbow_offset + wrist_1_length = 0.10915 -->
    <!--property name="upper_arm_length" value="0.42500" /-->
    <!--property name="elbow_offset" value="0.1197" /-->
    <!-- CAD measured -->
    <!--property name="forearm_length" value="0.39225" /-->
    <!--property name="wrist_1_length" value="0.093" /-->
    <!-- CAD measured -->
    <!--property name="wrist_2_length" value="0.09465" /-->
    <!-- In CAD this distance is 0.930, but in the spec it is 0.09465 -->
    <!--property name="wrist_3_length" value="0.0823" /-->
    <!-- manually measured -->
    <link name="base_link">
        <visual>
            <geometry>
                <mesh filename="package://ur_description/meshes/ur5/visual/base.dae" />
            </geometry>
            <material name="LightGrey">
                <color rgba="0.7 0.7 0.7 1.0" />
            </material>
        </visual>
        <collision>
            <geometry>
                <mesh filename="package://ur_description/meshes/ur5/collision/base.stl" />
            </geometry>
        </collision>
        
<inertial>
            <mass value="4.0" />
            <origin rpy="0 0 0" xyz="0.0 0.0 0.0" />
            <inertia ixx="0.00443333156" ixy="0.0" ixz="0.0" iyy="0.00443333156" iyz="0.0" izz="0.0072" />
        </inertial>

    </link>
    <joint name="shoulder_pan_joint" type="revolute">
        <parent link="base_link" />
        <child link="shoulder_link" />
        <origin rpy="0 0.0 3.14159265359" xyz="0.0 0.0 0.089159" />
        <axis xyz="0 0 1" />
        <limit effort="150.0" lower="-3.14159265359" upper="3.14159265359" velocity="3.15" />
        <dynamics damping="0.0" friction="0.0" />
    </joint>
    <link name="shoulder_link">
        <visual>
            <geometry>
                <mesh filename="package://ur_description/meshes/ur5/visual/shoulder.dae" />
            </geometry>
            <material name="LightGrey">
                <color rgba="0.7 0.7 0.7 1.0" />
            </material>
        </visual>
        <collision>
            <geometry>
                <mesh filename="package://ur_description/meshes/ur5/collision/shoulder.stl" />
            </geometry>
        </collision>
        
<inertial>
            <mass value="3.7" />
            <origin rpy="0 0 0" xyz="0.0 0.0 0.0" />
            <inertia ixx="0.010267495893" ixy="0.0" ixz="0.0" iyy="0.010267495893" iyz="0.0" izz="0.00666" />
        </inertial>

    </link>
    <joint name="shoulder_lift_joint" type="revolute">
        <parent link="shoulder_link" />
        <child link="upper_arm_link" />
        <origin rpy="0.0 -1.57079632679 0.0" xyz="0.0 0.13585 0.0" />
        <axis xyz="0 1 0" />
        <limit effort="150.0" lower="-3.14159265359" upper="3.14159265359" velocity="3.15" />
        <dynamics damping="0.0" friction="0.0" />
    </joint>
    <link name="upper_arm_link">
        <visual>
            <geometry>
                <mesh filename="package://ur_description/meshes/ur5/visual/upperarm.dae" />
            </geometry>
            <material name="LightGrey">
                <color rgba="0.7 0.7 0.7 1.0" />
            </material>
        </visual>
        <collision>
            <geometry>
                <mesh filename="package://ur_description/meshes/ur5/collision/upperarm.stl" />
            </geometry>
        </collision>
        
<inertial>
            <mass value="8.393" />
            <origin rpy="0 0 0" xyz="0.0 0.0 0.28" />
            <inertia ixx="0.22689067591" ixy="0.0" ixz="0.0" iyy="0.22689067591" iyz="0.0" izz="0.0151074" />
        </inertial>

    </link>
    <joint name="elbow_joint" type="revolute">
        <parent link="upper_arm_link" />
        <child link="forearm_link" />
        <origin rpy="0.0 2.78 0.0" xyz="0.0 -0.1197 0.425" />
        <axis xyz="0 1 0" />
        <limit effort="150.0" lower="-3.14159265359" upper="3.14159265359" velocity="3.15" />
        <dynamics damping="0.0" friction="0.0" />
    </joint>
    <link name="forearm_link">
        <visual>
            <geometry>
                <mesh filename="package://ur_description/meshes/ur5/visual/forearm.dae" />
            </geometry>
            <material name="LightGrey">
                <color rgba="0.7 0.7 0.7 1.0" />
            </material>
        </visual>
        <collision>
            <geometry>
                <mesh filename="package://ur_description/meshes/ur5/collision/forearm.stl" />
            </geometry>
        </collision>
        
<inertial>
            <mass value="2.275" />
            <origin rpy="0 0 0" xyz="0.0 0.0 0.196125" />
            <inertia ixx="0.0312167910289" ixy="0.0" ixz="0.0" iyy="0.0312167910289" iyz="0.0" izz="0.004095" />
        </inertial>

    </link>
    <joint name="wrist_1_joint" type="revolute">
        <parent link="forearm_link" />
        <child link="wrist_1_link" />
        <origin rpy="0.0 -1.57079632679 0.0" xyz="0.0 0.0 0.39225" />
        <axis xyz="0 1 0" />
        <limit effort="28.0" lower="-3.14159265359" upper="3.14159265359" velocity="3.2" />
        <dynamics damping="0.0" friction="0.0" />
    </joint>
    <link name="wrist_1_link">
        <visual>
            <geometry>
                <mesh filename="package://ur_description/meshes/ur5/visual/wrist1.dae" />
            </geometry>
            <material name="LightGrey">
                <color rgba="0.7 0.7 0.7 1.0" />
            </material>
        </visual>
        <collision>
            <geometry>
                <mesh filename="package://ur_description/meshes/ur5/collision/wrist1.stl" />
            </geometry>
        </collision>
        
<inertial>
            <mass value="1.219" />
            <origin rpy="0 0 0" xyz="0.0 0.093 0.0" />
            <inertia ixx="0.00255989897604" ixy="0.0" ixz="0.0" iyy="0.00255989897604" iyz="0.0" izz="0.0021942" />
        </inertial>

    </link>
    <joint name="wrist_2_joint" type="revolute">
        <parent link="wrist_1_link" />
        <child link="wrist_2_link" />
        <origin rpy="0.0 0.0 1.57079632679" xyz="0.0 0.093 0.0" />
        <axis xyz="0 0 1" />
        <limit effort="28.0" lower="-3.14159265359" upper="3.14159265359" velocity="3.2" />
        <dynamics damping="0.0" friction="0.0" />
    </joint>
    <link name="wrist_2_link">
        <visual>
            <geometry>
                <mesh filename="package://ur_description/meshes/ur5/visual/wrist2.dae" />
            </geometry>
            <material name="LightGrey">
                <color rgba="0.7 0.7 0.7 1.0" />
            </material>
        </visual>
        <collision>
            <geometry>
                <mesh filename="package://ur_description/meshes/ur5/collision/wrist2.stl" />
            </geometry>
        </collision>
        
<inertial>
            <mass value="1.219" />
            <origin rpy="0 0 0" xyz="0.0 0.0 0.09465" />
            <inertia ixx="0.00255989897604" ixy="0.0" ixz="0.0" iyy="0.00255989897604" iyz="0.0" izz="0.0021942" />
        </inertial>

    </link>
    <joint name="wrist_3_joint" type="revolute">
        <parent link="wrist_2_link" />
        <child link="wrist_3_link" />
        <origin rpy="0.0 1.57079632679 0.0" xyz="0.0 0.0 0.09465" />
        <axis xyz="0 1 0" />
        <limit effort="28.0" lower="-3.14159265359" upper="3.14159265359" velocity="3.2" />
        <dynamics damping="0.0" friction="0.0" />
    </joint>
    <link name="wrist_3_link">
        <visual>
            <geometry>
                <mesh filename="package://ur_description/meshes/ur5/visual/wrist3.dae" />
            </geometry>
            <material name="LightGrey">
                <color rgba="0.7 0.7 0.7 1.0" />
            </material>
        </visual>
        <collision>
            <geometry>
                <mesh filename="package://ur_description/meshes/ur5/collision/wrist3.stl" />
            </geometry>
        </collision>
        
<inertial>
            <mass value="0.1879" />
            <origin rpy="1.57079632679 0 0" xyz="0.0 0.06505 0.0" />
            <inertia ixx="8.46958911216e-05" ixy="0.0" ixz="0.0" iyy="8.46958911216e-05" iyz="0.0" izz="0.0001321171875" />
        </inertial>

    </link>
    <joint name="ee_fixed_joint" type="fixed">
        <parent link="wrist_3_link" />
        <child link="ee_link" />
        <origin rpy="0.0 0.0 1.57079632679" xyz="0.0 0.0823 0.0" />
    </joint>
    <link name="ee_link">
        <collision>
            <geometry>
                <box size="0.01 0.01 0.01" />
            </geometry>
            <origin rpy="0 0 0" xyz="-0.01 0 0" />
        </collision>
        
<inertial>
            <mass value="0.1" />
            <inertia ixx="0.03" iyy="0.03" izz="0.03" ixy="0.0" ixz="0.0" iyz="0.0" />
        </inertial>

    </link>
    <transmission name="shoulder_pan_trans">
        <type>transmission_interface/SimpleTransmission</type>
        <joint name="shoulder_pan_joint">
            <hardwareInterface>hardware_interface/PositionJointInterface</hardwareInterface>
        </joint>
        <actuator name="shoulder_pan_motor">
            <mechanicalReduction>1</mechanicalReduction>
        </actuator>
    </transmission>
    <transmission name="shoulder_lift_trans">
        <type>transmission_interface/SimpleTransmission</type>
        <joint name="shoulder_lift_joint">
            <hardwareInterface>hardware_interface/PositionJointInterface</hardwareInterface>
        </joint>
        <actuator name="shoulder_lift_motor">
            <mechanicalReduction>1</mechanicalReduction>
        </actuator>
    </transmission>
    <transmission name="elbow_trans">
        <type>transmission_interface/SimpleTransmission</type>
        <joint name="elbow_joint">
            <hardwareInterface>hardware_interface/PositionJointInterface</hardwareInterface>
        </joint>
        <actuator name="elbow_motor">
            <mechanicalReduction>1</mechanicalReduction>
        </actuator>
    </transmission>
    <transmission name="wrist_1_trans">
        <type>transmission_interface/SimpleTransmission</type>
        <joint name="wrist_1_joint">
            <hardwareInterface>hardware_interface/PositionJointInterface</hardwareInterface>
        </joint>
        <actuator name="wrist_1_motor">
            <mechanicalReduction>1</mechanicalReduction>
        </actuator>
    </transmission>
    <transmission name="wrist_2_trans">
        <type>transmission_interface/SimpleTransmission</type>
        <joint name="wrist_2_joint">
            <hardwareInterface>hardware_interface/PositionJointInterface</hardwareInterface>
        </joint>
        <actuator name="wrist_2_motor">
            <mechanicalReduction>1</mechanicalReduction>
        </actuator>
    </transmission>
    <transmission name="wrist_3_trans">
        <type>transmission_interface/SimpleTransmission</type>
        <joint name="wrist_3_joint">
            <hardwareInterface>hardware_interface/PositionJointInterface</hardwareInterface>
        </joint>
        <actuator name="wrist_3_motor">
            <mechanicalReduction>1</mechanicalReduction>
        </actuator>
    </transmission>
    <gazebo reference="shoulder_link">
        <selfCollide>true</selfCollide>
    </gazebo>
    <gazebo reference="upper_arm_link">
        <selfCollide>true</selfCollide>
    </gazebo>
    <gazebo reference="forearm_link">
        <selfCollide>true</selfCollide>
    </gazebo>
    <gazebo reference="wrist_1_link">
        <selfCollide>true</selfCollide>
    </gazebo>
    <gazebo reference="wrist_3_link">
        <selfCollide>true</selfCollide>
    </gazebo>
    <gazebo reference="wrist_2_link">
        <selfCollide>true</selfCollide>
    </gazebo>
    <gazebo reference="ee_link">
        <selfCollide>true</selfCollide>
    </gazebo>
    <!-- ROS base_link to UR 'Base' Coordinates transform -->
    <link name="base" />
    <joint name="base_link-base_fixed_joint" type="fixed">
        <!-- NOTE: this rotation is only needed as long as base_link itself is
                 not corrected wrt the real robot (ie: rotated over 180
                 degrees)
      -->
        <origin rpy="0 0 -3.14159265359" xyz="0 0 0" />
        <parent link="base_link" />
        <child link="base" />
    </joint>
    <!-- Frame coincident with all-zeros TCP on UR controller -->
    <link name="tool0" />
    <joint name="wrist_3_link-tool0_fixed_joint" type="fixed">
        <origin rpy="-1.57079632679 0 0" xyz="0 0.0823 0" />
        <parent link="wrist_3_link" />
        <child link="tool0" />
    </joint>
    <link name="base_link_main">
        
<inertial>
            <origin rpy="-3.14159265359 0 0" xyz="0 0 0" />
            <mass value="20.4660866954057" />
            <inertia ixx="0.193568038684775" ixy="0.00548623614276343" ixz="-6.15228083843436E-05" iyy="0.108859012808764" iyz="-0.00384844545395753" izz="0.229327239703698" />
        </inertial>

        <visual>
            <origin rpy="3.14159265359 0 0" xyz="0.211886378 -0.81046675318 .51736994677" />
            <geometry>
                <mesh filename="package://v5_asm/meshes/base_link.dae" />
            </geometry>
            <material name="">
                <color rgba="0.752941176470588 0.752941176470588 0.752941176470588 1" />
            </material>
        </visual>
        <collision>
            <origin rpy="3.14159265359 0 0" xyz="0.211886378 -0.81046675318 .51736994677" />
            <geometry>
                <mesh filename="package://v5_asm/meshes/base_link_main.dae" />
            </geometry>
        </collision>
    </link>
    <joint name="world_to_base" type="fixed">
        <parent link="world" />
        <child link="base_link_main" />
        <origin rpy="0.0 0.0 0.0" xyz="0.0 0.0 0.0" />
    </joint>
    <link name="arm_stand">
        
<inertial>
            <origin rpy="0 0 0" xyz="-0.0449002179804069 -0.00120158576170751 -0.0786427433397576" />
            <mass value="1.50525286307822" />
            <inertia ixx="0.00548888032967621" ixy="1.929980925743E-05" ixz="-0.00180882087465193" iyy="0.00662090700121496" iyz="6.80641116194522E-06" izz="0.00455713436329697" />
        </inertial>

        <visual>
            <origin rpy="0 0 0" xyz="0 0 0" />
            <geometry>
                <mesh filename="package://v5_asm/meshes/arm_stand.dae" />
            </geometry>
            <material name="">
                <color rgba="0.792156862745098 0.819607843137255 0.933333333333333 1" />
            </material>
        </visual>
        <collision>
            <origin rpy="0 0 0" xyz="0 0 0" />
            <geometry>
                <mesh filename="package://v5_asm/meshes/arm_stand.dae" />
            </geometry>
        </collision>
    </link>
    <joint name="arm_stand" type="fixed">
        <origin rpy="0 -0.5236 1.5708" xyz="0.17434 -0.98064 0.86287" />
        <parent link="base_link_main" />
        <child link="arm_stand" />
        <axis xyz="0.5 0 0.86603" />
    </joint>
    <joint name="stand_to_arm" type="fixed">
        <origin rpy="0 0 0" xyz="0 0 0.016" />
        <parent link="arm_stand" />
        <child link="base_link" />
        <axis xyz="0.86603 -0.022933 0.49947" />
    </joint>
    <!-- inches -->
    <!-- inches -->
    <!-- colors -->
    <material name="light_grey">
        <color rgba="0.7 0.7 0.7 1" />
    </material>
    <material name="dark_grey">
        <color rgba="0.5 0.5 0.5 1" />
    </material>
    <material name="black">
        <color rgba="0 0 0 1" />
    </material>
    <material name="almost_black">
        <color rgba="0.02 0.02 0.02 1" />
    </material>
    <!-- <gazebo> -->
    <!--   <plugin name="gazebo_ros_control" filename="libgazebo_ros_control.so"> -->
    <!--     <robotNamespace>/</robotNamespace> -->
    <!--   </plugin> -->
    <!-- </gazebo> -->
    <!-- Base footprint is the center of the robot's chassis between the motors projected on the ground change base_link_2 to base_link
    <link name="base_footprint"/-->
    <!-- base_link is another name for base_footprint, Another name for the ground projection that is used in all segbot codebase-->
    <link name="base_link_2" />
    <joint name="base_footprint_joint" type="fixed">
        <origin rpy="0 0 1.57079632679" xyz="0.232104567 -0.81046675318 0.24551258" />
        <parent link="base_link_main" />
        <child link="base_link_2" />
    </joint>
    <joint name="base_chassis_joint" type="fixed">
        <origin rpy="0 0 0" xyz="0 0 0.15801795" />
        <parent link="base_link_2" />
        <child link="base_chassis_link" />
    </joint>
    <link name="base_chassis_link">
        <visual>
            <geometry>
                <mesh filename="package://segway_description/meshes/visual/std_gearbox_chassis.dae" />
            </geometry>
        </visual>
    </link>
    <link name="inertial_collision_link">
        
<inertial>
            <mass value="36.914402" />
            <origin xyz="-0.043407 0.000037 0.060079" />
            <inertia ixx="1.182744" ixy="0.017957" ixz="-0.077476" iyx="0.017957" iyy="0.538664" iyz="0.000018" izx="-0.077476" izy="0.000018" izz="1.240229" />
        </inertial>

        <collision>
            <geometry>
                <mesh filename="package://segway_description/meshes/collision/RMP210_chassis_collision.stl" />
            </geometry>
        </collision>
    </link>
    <joint name="inertial_collision_joint" type="fixed">
        <parent link="base_chassis_link" />
        <child link="inertial_collision_link" />
    </joint>
    <joint name="left_spacer_joint" type="fixed">
        <origin rpy="0 0 0" xyz="0 0.19582 0.00665015" />
        <parent link="base_chassis_link" />
        <child link="left_spacer_link" />
    </joint>
    <link name="left_spacer_link">
        <visual>
            <geometry>
                <mesh filename="package://segway_description/meshes/visual/single_spacer.dae" />
            </geometry>
        </visual>
    </link>
    <joint name="right_spacer_joint" type="fixed">
        <origin rpy="0 0 3.14159265359" xyz="0 -0.19582 0.00665015" />
        <parent link="base_chassis_link" />
        <child link="right_spacer_link" />
    </joint>
    <link name="right_spacer_link">
        <visual>
            <geometry>
                <mesh filename="package://segway_description/meshes/visual/single_spacer.dae" />
            </geometry>
        </visual>
    </link>
    <joint name="mcu_1_battery_joint" type="fixed">
        <origin rpy="0 0 0" xyz="-0.09298 0 0" />
        <parent link="base_chassis_link" />
        <child link="mcu_1_battery_link" />
    </joint>
    <link name="mcu_1_battery_link">
        <visual>
            <geometry>
                <mesh filename="package://segway_description/meshes/visual/battery.dae" />
            </geometry>
        </visual>
    </link>
    <joint name="aux_battery_joint" type="fixed">
        <origin rpy="0 0 3.14159265359" xyz="0.09298 0 0" />
        <parent link="base_chassis_link" />
        <child link="aux_battery_link" />
    </joint>
    <link name="aux_battery_link">
        <visual>
            <geometry>
                <mesh filename="package://segway_description/meshes/visual/battery.dae" />
            </geometry>
        </visual>
    </link>
    <link name="left_wheel_link">
        
<inertial>
            <mass value="4.195729" />
            <origin xyz="0 0 0" />
            <inertia ixx="0.063680" ixy="0.000000" ixz="0.000000" iyx="0.000000" iyy="0.121410" iyz="0.000000" izx="0.000000" izy="0.000000" izz="0.063680" />
        </inertial>

        <visual>
            <origin rpy="0 0 0.0" xyz="0 0 0" />
            <geometry>
                <mesh filename="package://segway_description/meshes/visual/i2_wheel.dae" />
            </geometry>
        </visual>
        <collision>
            <origin rpy="1.5707963268 0 0" xyz="0 0 0" />
            <geometry>
                <cylinder length="0.092249" radius="0.2405681" />
            </geometry>
        </collision>
    </link>
    <gazebo reference="left_wheel_link">
        <mu1 value="10.0" />
        <mu2 value="10.0" />
        <kp value="10000000.0" />
        <kd value="10.0" />
        <fdir1 value="1 0 0" />
        <minDepth>0.003</minDepth>
    </gazebo>
    <joint name="left_wheel" type="continuous">
        <parent link="base_chassis_link" />
        <child link="left_wheel_link" />
        <origin rpy="0 0 0" xyz="0 0.2395555 0.08255015" />
        <axis rpy="0 0 0" xyz="0 1 0" />
    </joint>
    <transmission name="left_wheel_trans" type="SimpleTransmission">
        <type>transmission_interface/SimpleTransmission</type>
        <actuator name="left_wheel_motor">
            <mechanicalReduction>1</mechanicalReduction>
        </actuator>
        <joint name="left_wheel">
            <hardwareInterface>VelocityJointInterface</hardwareInterface>
        </joint>
    </transmission>
    <link name="right_wheel_link">
        
<inertial>
            <mass value="4.195729" />
            <origin xyz="0 0 0" />
            <inertia ixx="0.063680" ixy="0.000000" ixz="0.000000" iyx="0.000000" iyy="0.121410" iyz="0.000000" izx="0.000000" izy="0.000000" izz="0.063680" />
        </inertial>

        <visual>
            <origin rpy="0 0 3.14159265359" xyz="0 0 0" />
            <geometry>
                <mesh filename="package://segway_description/meshes/visual/i2_wheel.dae" />
            </geometry>
        </visual>
        <collision>
            <origin rpy="1.5707963268 0 0" xyz="0 0 0" />
            <geometry>
                <cylinder length="0.092249" radius="0.2405681" />
            </geometry>
        </collision>
    </link>
    <gazebo reference="right_wheel_link">
        <mu1 value="10.0" />
        <mu2 value="10.0" />
        <kp value="10000000.0" />
        <kd value="10.0" />
        <fdir1 value="1 0 0" />
        <minDepth>0.003</minDepth>
    </gazebo>
    <joint name="right_wheel" type="continuous">
        <parent link="base_chassis_link" />
        <child link="right_wheel_link" />
        <origin rpy="0 0 0" xyz="0 -0.2395555 0.08255015" />
        <axis rpy="0 0 0" xyz="0 1 0" />
    </joint>
    <transmission name="right_wheel_trans" type="SimpleTransmission">
        <type>transmission_interface/SimpleTransmission</type>
        <actuator name="right_wheel_motor">
            <mechanicalReduction>1</mechanicalReduction>
        </actuator>
        <joint name="right_wheel">
            <hardwareInterface>VelocityJointInterface</hardwareInterface>
        </joint>
    </transmission>
    <joint name="rear_caster_plate_joint" type="fixed">
        <origin rpy="0 0 0" xyz="-0.31472057 0 0.02425235" />
        <parent link="base_chassis_link" />
        <child link="rear_caster_plate_link" />
    </joint>
    <link name="rear_caster_plate_link">
        
<inertial>
            <mass value="4.487241" />
            <origin xyz="0.027375 0 0.016101" />
            <inertia ixx="0.070527" ixy="0.000000" ixz="-0.001013" iyx="0.000000" iyy="0.010678" iyz="0.000000" izx="-0.001013" izy="0.000000" izz="0.078313" />
        </inertial>

        <visual>
            <geometry>
                <mesh filename="package://segway_description/meshes/visual/caster_plate.dae" />
            </geometry>
        </visual>
        <collision>
            <geometry>
                <mesh filename="package://segway_description/meshes/collision/caster_plate_collision.stl" />
            </geometry>
        </collision>
    </link>
    <link name="rear_caster_swivel_link">
        
<inertial>
            <mass value="0.579519" />
            <origin xyz="-0.020596 0.000280 -0.055367" />
            <inertia ixx="0.001361" ixy="-0.000003" ixz="0.000347" iyx="-0.000003" iyy="0.001287" iyz="-0.000010" izx="0.000347" izy="-0.000010" izz="0.000632" />
        </inertial>

        <visual>
            <geometry>
                <mesh filename="package://segway_description/meshes/visual/caster_bracket.dae" />
            </geometry>
        </visual>
        <collision>
            <geometry>
                <mesh filename="package://segway_description/meshes/collision/caster_bracket_collision.stl" />
            </geometry>
        </collision>
    </link>
    <gazebo reference="rear_caster_swivel_link">
        <mu1 value="100.0" />
        <mu2 value="100.0" />
        <kp value="10000000.0" />
        <kd value="1.0" />
    </gazebo>
    <joint name="rear_caster_swivel" type="continuous">
        <parent link="rear_caster_plate_link" />
        <child link="rear_caster_swivel_link" />
        <!--xacro:insert_block name="joint_pose"/-->
        <axis xyz="0 0 1" />
        <anchor xyz="0 0 0" />
        <limit effort="0.0" velocity="1000" />
        <dynamics damping="0.7" />
    </joint>
    <transmission name="rear_caster_swivel_trans" type="SimpleTransmission">
        <type>transmission_interface/SimpleTransmission</type>
        <joint name="rear_caster_swivel">
            <hardwareInterface>EffortJointInterface</hardwareInterface>
        </joint>
        <actuator name="rear_caster_swivel_motor">
            <hardwareInterface>EffortJointInterface</hardwareInterface>
            <mechanicalReduction>1</mechanicalReduction>
        </actuator>
    </transmission>
    <link name="rear_caster_wheel_link">
        
<inertial>
            <mass value="1.25" />
            <origin xyz="0 0 0" />
            <inertia ixx="0.001442" ixy="0.000000" ixz="0.000000" iyx="0.000000" iyy="0.002493" iyz="0.000000" izx="0.000000" izy="0.000000" izz="0.001442" />
        </inertial>

        <visual>
            <geometry>
                <mesh filename="package://segway_description/meshes/visual/caster_wheel.dae" />
            </geometry>
        </visual>
        <collision>
            <origin rpy="1.5707963268 0 0" xyz="0 0 0" />
            <geometry>
                <cylinder length="0.050" radius="0.0762" />
            </geometry>
        </collision>
    </link>
    <gazebo reference="rear_caster_wheel_link">
        <mu1 value="100.0" />
        <mu2 value="100.0" />
        <kp value="10000000.0" />
        <kd value="10.0" />
        <fdir1 value="1 0 0" />
        <minDepth>0.003</minDepth>
    </gazebo>
    <joint name="rear_caster_wheel" type="continuous">
        <parent link="rear_caster_swivel_link" />
        <child link="rear_caster_wheel_link" />
        <origin rpy="0 0 0" xyz="-0.03782 0 -0.10608" />
        <axis xyz="0 1 0" />
        <anchor xyz="-0.03782 0 -0.10608" />
        <limit effort="0.0" velocity="1000" />
        <dynamics damping="0.2" />
    </joint>
    <transmission name="rear_caster_wheel_trans" type="SimpleTransmission">
        <type>transmission_interface/SimpleTransmission</type>
        <joint name="rear_caster_wheel">
            <hardwareInterface>EffortJointInterface</hardwareInterface>
        </joint>
        <actuator name="rear_caster_wheel_motor">
            <hardwareInterface>EffortJointInterface</hardwareInterface>
            <mechanicalReduction>1</mechanicalReduction>
        </actuator>
    </transmission>
    <joint name="front_caster_plate_joint" type="fixed">
        <origin rpy="0 0 3.14159265359" xyz="0.31472057 0 0.02425235" />
        <parent link="base_chassis_link" />
        <child link="front_caster_plate_link" />
    </joint>
    <link name="front_caster_plate_link">
        
<inertial>
            <mass value="4.487241" />
            <origin xyz="0.027375 0 0.016101" />
            <inertia ixx="0.070527" ixy="0.000000" ixz="-0.001013" iyx="0.000000" iyy="0.010678" iyz="0.000000" izx="-0.001013" izy="0.000000" izz="0.078313" />
        </inertial>

        <visual>
            <geometry>
                <mesh filename="package://segway_description/meshes/visual/caster_plate.dae" />
            </geometry>
        </visual>
        <collision>
            <geometry>
                <mesh filename="package://segway_description/meshes/collision/caster_plate_collision.stl" />
            </geometry>
        </collision>
    </link>
    <link name="front_caster_swivel_link">
        
<inertial>
            <mass value="0.579519" />
            <origin xyz="-0.020596 0.000280 -0.055367" />
            <inertia ixx="0.001361" ixy="-0.000003" ixz="0.000347" iyx="-0.000003" iyy="0.001287" iyz="-0.000010" izx="0.000347" izy="-0.000010" izz="0.000632" />
        </inertial>

        <visual>
            <geometry>
                <mesh filename="package://segway_description/meshes/visual/caster_bracket.dae" />
            </geometry>
        </visual>
        <collision>
            <geometry>
                <mesh filename="package://segway_description/meshes/collision/caster_bracket_collision.stl" />
            </geometry>
        </collision>
    </link>
    <gazebo reference="front_caster_swivel_link">
        <mu1 value="100.0" />
        <mu2 value="100.0" />
        <kp value="10000000.0" />
        <kd value="1.0" />
    </gazebo>
    <joint name="front_caster_swivel" type="continuous">
        <parent link="front_caster_plate_link" />
        <child link="front_caster_swivel_link" />
        <!--xacro:insert_block name="joint_pose"/-->
        <axis xyz="0 0 1" />
        <anchor xyz="0 0 0" />
        <limit effort="0.0" velocity="1000" />
        <dynamics damping="0.7" />
    </joint>
    <transmission name="front_caster_swivel_trans" type="SimpleTransmission">
        <type>transmission_interface/SimpleTransmission</type>
        <joint name="front_caster_swivel">
            <hardwareInterface>EffortJointInterface</hardwareInterface>
        </joint>
        <actuator name="front_caster_swivel_motor">
            <hardwareInterface>EffortJointInterface</hardwareInterface>
            <mechanicalReduction>1</mechanicalReduction>
        </actuator>
    </transmission>
    <link name="front_caster_wheel_link">
        
<inertial>
            <mass value="1.25" />
            <origin xyz="0 0 0" />
            <inertia ixx="0.001442" ixy="0.000000" ixz="0.000000" iyx="0.000000" iyy="0.002493" iyz="0.000000" izx="0.000000" izy="0.000000" izz="0.001442" />
        </inertial>

        <visual>
            <geometry>
                <mesh filename="package://segway_description/meshes/visual/caster_wheel.dae" />
            </geometry>
        </visual>
        <collision>
            <origin rpy="1.5707963268 0 0" xyz="0 0 0" />
            <geometry>
                <cylinder length="0.050" radius="0.0762" />
            </geometry>
        </collision>
    </link>
    <gazebo reference="front_caster_wheel_link">
        <mu1 value="100.0" />
        <mu2 value="100.0" />
        <kp value="10000000.0" />
        <kd value="10.0" />
        <fdir1 value="1 0 0" />
        <minDepth>0.003</minDepth>
    </gazebo>
    <joint name="front_caster_wheel" type="continuous">
        <parent link="front_caster_swivel_link" />
        <child link="front_caster_wheel_link" />
        <origin rpy="0 0 0" xyz="-0.03782 0 -0.10608" />
        <axis xyz="0 1 0" />
        <anchor xyz="-0.03782 0 -0.10608" />
        <limit effort="0.0" velocity="1000" />
        <dynamics damping="0.2" />
    </joint>
    <transmission name="front_caster_wheel_trans" type="SimpleTransmission">
        <type>transmission_interface/SimpleTransmission</type>
        <joint name="front_caster_wheel">
            <hardwareInterface>EffortJointInterface</hardwareInterface>
        </joint>
        <actuator name="front_caster_wheel_motor">
            <hardwareInterface>EffortJointInterface</hardwareInterface>
            <mechanicalReduction>1</mechanicalReduction>
        </actuator>
    </transmission>
    <link name="robotiq_arg2f_base_link">
        
<inertial>
            <origin rpy="0 0 0" xyz="8.625E-08 -4.6583E-06 0.03145" />
            <mass value="0.22652" />
            <inertia ixx="0.00020005" ixy="-4.2442E-10" ixz="-2.9069E-10" iyy="0.00017832" iyz="-3.4402E-08" izz="0.00013478" />
        </inertial>

        <visual>
            <origin rpy="0 0 0" xyz="0 0 0" />
            <geometry>
                <mesh filename="package://robotiq_2f_140_gripper_visualization/meshes/visual/robotiq_arg2f_base_link.stl" />
            </geometry>
            <material name="">
                <color rgba="0.1 0.1 0.1 1" />
            </material>
        </visual>
        <collision>
            <origin rpy="0 0 0" xyz="0 0 0" />
            <geometry>
                <mesh filename="package://robotiq_2f_140_gripper_visualization/meshes/collision/robotiq_arg2f_base_link.stl" />
            </geometry>
        </collision>
    </link>
    <joint name="arm_to_gripper" type="fixed">
        <parent link="wrist_3_link" />
        <child link="robotiq_arg2f_base_link" />
        <origin rpy="-1.57079632679 0 0" xyz="0 .0772199 0" />
    </joint>
    <link name="left_outer_knuckle">
        
<inertial>
            <origin rpy="0 0 0" xyz="-0.000200000000003065 0.0199435877845359 0.0292245259211331" />
            <mass value="0.00853198276973456" />
            <inertia ixx="2.89328108496468E-06" ixy="-1.57935047237397E-19" ixz="-1.93980378593255E-19" iyy="1.86719750325683E-06" iyz="-1.21858577871576E-06" izz="1.21905238907251E-06" />
        </inertial>

        <visual>
            <origin rpy="0 0 0" xyz="0 0 0" />
            <geometry>
                <mesh filename="package://robotiq_2f_140_gripper_visualization/meshes/visual/robotiq_arg2f_140_outer_knuckle.stl" />
            </geometry>
            <material name="">
                <color rgba="0.792156862745098 0.819607843137255 0.933333333333333 1" />
            </material>
        </visual>
        <collision>
            <origin rpy="0 0 0" xyz="0 0 0" />
            <geometry>
                <mesh filename="package://robotiq_2f_140_gripper_visualization/meshes/collision/robotiq_arg2f_140_outer_knuckle.stl" />
            </geometry>
        </collision>
    </link>
    <link name="left_outer_finger">
        
<inertial>
            <origin rpy="0 0 0" xyz="0.00030115855001899 0.0373907951953854 -0.0208027427000385" />
            <mass value="0.022614240507152" />
            <inertia ixx="1.52518312458174E-05" ixy="9.76583423954399E-10" ixz="-5.43838577022588E-10" iyy="6.17694243867776E-06" iyz="6.78636130740228E-06" izz="1.16494917907219E-05" />
        </inertial>

        <visual>
            <origin rpy="0 0 0" xyz="0 0 0" />
            <geometry>
                <mesh filename="package://robotiq_2f_140_gripper_visualization/meshes/visual/robotiq_arg2f_140_outer_finger.stl" />
            </geometry>
            <material name="">
                <color rgba="0.1 0.1 0.1 1" />
            </material>
        </visual>
        <collision>
            <origin rpy="0 0 0" xyz="0 0 0" />
            <geometry>
                <mesh filename="package://robotiq_2f_140_gripper_visualization/meshes/collision/robotiq_arg2f_140_outer_finger.stl" />
            </geometry>
        </collision>
    </link>
    <link name="left_inner_finger">
        
<inertial>
            <origin rpy="0 0 0" xyz="0.000299999999999317 0.0160078233491243 -0.0136945669206257" />
            <mass value="0.0104003125914103" />
            <inertia ixx="2.71909453810972E-06" ixy="1.35402465472579E-21" ixz="-7.1817349065269E-22" iyy="7.69100314106116E-07" iyz="6.74715432769696E-07" izz="2.30315190420171E-06" />
        </inertial>

        <visual>
            <origin rpy="0 0 0" xyz="0 0 0" />
            <geometry>
                <mesh filename="package://robotiq_2f_140_gripper_visualization/meshes/visual/robotiq_arg2f_140_inner_finger.stl" />
            </geometry>
            <material name="">
                <color rgba="0.1 0.1 0.1 1" />
            </material>
        </visual>
        <collision>
            <origin rpy="0 0 0" xyz="0 0 0" />
            <geometry>
                <mesh filename="package://robotiq_2f_140_gripper_visualization/meshes/collision/robotiq_arg2f_140_inner_finger.stl" />
            </geometry>
        </collision>
    </link>
    <link name="left_inner_finger_pad">
        <visual>
            <origin rpy="0 0 0" xyz="0 0 0" />
            <geometry>
                <box size="0.027 0.065 0.0075" />
            </geometry>
            <material name="">
                <color rgba="0.9 0.9 0.9 1" />
            </material>
        </visual>
        <collision>
            <origin rpy="0 0 0" xyz="0 0 0" />
            <geometry>
                <box size="0.03 0.07 0.0075" />
            </geometry>
            <material name="">
                <color rgba="0.9 0.0 0.0 1" />
            </material>
        </collision>
        
<inertial>
            <mass value="0.1" />
            <inertia ixx="0.03" iyy="0.03" izz="0.03" ixy="0.0" ixz="0.0" iyz="0.0" />
        </inertial>

    </link>
    <link name="left_inner_knuckle">
        
<inertial>
            <origin rpy="0 0 0" xyz="0.000123011831763771 0.0507850843201817 0.00103968640075166" />
            <mass value="0.0271177346495152" />
            <inertia ixx="2.61910379223783E-05" ixy="-2.43616858946494E-07" ixz="-6.37789906117123E-09" iyy="2.8270243746167E-06" iyz="-5.37200748039765E-07" izz="2.83695868220296E-05" />
        </inertial>

        <visual>
            <origin rpy="0 0 0" xyz="0 0 0" />
            <geometry>
                <mesh filename="package://robotiq_2f_140_gripper_visualization/meshes/visual/robotiq_arg2f_140_inner_knuckle.stl" />
            </geometry>
            <material name="">
                <color rgba="0.1 0.1 0.1 1" />
            </material>
        </visual>
        <collision>
            <origin rpy="0 0 0" xyz="0 0 0" />
            <geometry>
                <mesh filename="package://robotiq_2f_140_gripper_visualization/meshes/collision/robotiq_arg2f_140_inner_knuckle.stl" />
            </geometry>
        </collision>
    </link>
    <link name="right_outer_knuckle">
        
<inertial>
            <origin rpy="0 0 0" xyz="-0.000200000000003065 0.0199435877845359 0.0292245259211331" />
            <mass value="0.00853198276973456" />
            <inertia ixx="2.89328108496468E-06" ixy="-1.57935047237397E-19" ixz="-1.93980378593255E-19" iyy="1.86719750325683E-06" iyz="-1.21858577871576E-06" izz="1.21905238907251E-06" />
        </inertial>

        <visual>
            <origin rpy="0 0 0" xyz="0 0 0" />
            <geometry>
                <mesh filename="package://robotiq_2f_140_gripper_visualization/meshes/visual/robotiq_arg2f_140_outer_knuckle.stl" />
            </geometry>
            <material name="">
                <color rgba="0.792156862745098 0.819607843137255 0.933333333333333 1" />
            </material>
        </visual>
        <collision>
            <origin rpy="0 0 0" xyz="0 0 0" />
            <geometry>
                <mesh filename="package://robotiq_2f_140_gripper_visualization/meshes/collision/robotiq_arg2f_140_outer_knuckle.stl" />
            </geometry>
        </collision>
    </link>
    <link name="right_outer_finger">
        
<inertial>
            <origin rpy="0 0 0" xyz="0.00030115855001899 0.0373907951953854 -0.0208027427000385" />
            <mass value="0.022614240507152" />
            <inertia ixx="1.52518312458174E-05" ixy="9.76583423954399E-10" ixz="-5.43838577022588E-10" iyy="6.17694243867776E-06" iyz="6.78636130740228E-06" izz="1.16494917907219E-05" />
        </inertial>

        <visual>
            <origin rpy="0 0 0" xyz="0 0 0" />
            <geometry>
                <mesh filename="package://robotiq_2f_140_gripper_visualization/meshes/visual/robotiq_arg2f_140_outer_finger.stl" />
            </geometry>
            <material name="">
                <color rgba="0.1 0.1 0.1 1" />
            </material>
        </visual>
        <collision>
            <origin rpy="0 0 0" xyz="0 0 0" />
            <geometry>
                <mesh filename="package://robotiq_2f_140_gripper_visualization/meshes/collision/robotiq_arg2f_140_outer_finger.stl" />
            </geometry>
        </collision>
    </link>
    <link name="right_inner_finger">
        
<inertial>
            <origin rpy="0 0 0" xyz="0.000299999999999317 0.0160078233491243 -0.0136945669206257" />
            <mass value="0.0104003125914103" />
            <inertia ixx="2.71909453810972E-06" ixy="1.35402465472579E-21" ixz="-7.1817349065269E-22" iyy="7.69100314106116E-07" iyz="6.74715432769696E-07" izz="2.30315190420171E-06" />
        </inertial>

        <visual>
            <origin rpy="0 0 0" xyz="0 0 0" />
            <geometry>
                <mesh filename="package://robotiq_2f_140_gripper_visualization/meshes/visual/robotiq_arg2f_140_inner_finger.stl" />
            </geometry>
            <material name="">
                <color rgba="0.1 0.1 0.1 1" />
            </material>
        </visual>
        <collision>
            <origin rpy="0 0 0" xyz="0 0 0" />
            <geometry>
                <mesh filename="package://robotiq_2f_140_gripper_visualization/meshes/collision/robotiq_arg2f_140_inner_finger.stl" />
            </geometry>
        </collision>
    </link>
    <link name="right_inner_finger_pad">
        <visual>
            <origin rpy="0 0 0" xyz="0 0 0" />
            <geometry>
                <box size="0.027 0.065 0.0075" />
            </geometry>
            <material name="">
                <color rgba="0.9 0.9 0.9 1" />
            </material>
        </visual>
        <collision>
            <origin rpy="0 0 0" xyz="0 0 0" />
            <geometry>
                <box size="0.03 0.07 0.0075" />
            </geometry>
            <material name="">
                <color rgba="0.9 0.0 0.0 1" />
            </material>
        </collision>
        
<inertial>
            <mass value="0.1" />
            <inertia ixx="0.03" iyy="0.03" izz="0.03" ixy="0.0" ixz="0.0" iyz="0.0" />
        </inertial>

    </link>
    <link name="right_inner_knuckle">
        
<inertial>
            <origin rpy="0 0 0" xyz="0.000123011831763771 0.0507850843201817 0.00103968640075166" />
            <mass value="0.0271177346495152" />
            <inertia ixx="2.61910379223783E-05" ixy="-2.43616858946494E-07" ixz="-6.37789906117123E-09" iyy="2.8270243746167E-06" iyz="-5.37200748039765E-07" izz="2.83695868220296E-05" />
        </inertial>

        <visual>
            <origin rpy="0 0 0" xyz="0 0 0" />
            <geometry>
                <mesh filename="package://robotiq_2f_140_gripper_visualization/meshes/visual/robotiq_arg2f_140_inner_knuckle.stl" />
            </geometry>
            <material name="">
                <color rgba="0.1 0.1 0.1 1" />
            </material>
        </visual>
        <collision>
            <origin rpy="0 0 0" xyz="0 0 0" />
            <geometry>
                <mesh filename="package://robotiq_2f_140_gripper_visualization/meshes/collision/robotiq_arg2f_140_inner_knuckle.stl" />
            </geometry>
        </collision>
    </link>
    <joint name="finger_joint" type="revolute">
        <origin rpy="2.29579632679 0 0" xyz="0 -0.030601 0.054905" />
        <parent link="robotiq_arg2f_base_link" />
        <child link="left_outer_knuckle" />
        <axis xyz="-1 0 0" />
        <limit effort="1000" lower="0" upper="0.7" velocity="2.0" />
    </joint>
    <joint name="left_outer_finger_joint" type="fixed">
        <origin rpy="0 0 0" xyz="0 0.01821998610742 0.0260018192872234" />
        <parent link="left_outer_knuckle" />
        <child link="left_outer_finger" />
        <axis xyz="1 0 0" />
    </joint>
    <joint name="left_inner_knuckle_joint" type="revolute">
        <origin rpy="2.29579632679 0 0.0" xyz="0 -0.0127 0.06142" />
        <parent link="robotiq_arg2f_base_link" />
        <child link="left_inner_knuckle" />
        <axis xyz="1 0 0" />
        <limit effort="1000" lower="-0.8757" upper="0.8757" velocity="2.0" />
        <mimic joint="finger_joint" multiplier="-1" offset="0" />
    </joint>
    <joint name="left_inner_finger_joint" type="revolute">
        <origin rpy="-0.725 0 0" xyz="0 0.0817554015893473 -0.0282203446692936" />
        <parent link="left_outer_finger" />
        <child link="left_inner_finger" />
        <axis xyz="1 0 0" />
        <limit effort="1000" lower="-0.8757" upper="0.8757" velocity="2.0" />
        <mimic joint="finger_joint" multiplier="1" offset="0" />
    </joint>
    <joint name="left_inner_finger_pad_joint" type="fixed">
        <origin rpy="0 0 0" xyz="0 0.0457554015893473 -0.0272203446692936" />
        <parent link="left_inner_finger" />
        <child link="left_inner_finger_pad" />
        <axis xyz="0 0 1" />
    </joint>
    <joint name="right_outer_knuckle_joint" type="revolute">
        <origin rpy="2.29579632679 0 3.14159265359" xyz="0 0.030601 0.054905" />
        <parent link="robotiq_arg2f_base_link" />
        <child link="right_outer_knuckle" />
        <axis xyz="1 0 0" />
        <limit effort="1000" lower="-0.725" upper="0.725" velocity="2.0" />
        <mimic joint="finger_joint" multiplier="-1" offset="0" />
    </joint>
    <joint name="right_outer_finger_joint" type="fixed">
        <origin rpy="0 0 0" xyz="0 0.01821998610742 0.0260018192872234" />
        <parent link="right_outer_knuckle" />
        <child link="right_outer_finger" />
        <axis xyz="1 0 0" />
    </joint>
    <joint name="right_inner_knuckle_joint" type="revolute">
        <origin rpy="2.29579632679 0 -3.14159265359" xyz="0 0.0127 0.06142" />
        <parent link="robotiq_arg2f_base_link" />
        <child link="right_inner_knuckle" />
        <axis xyz="1 0 0" />
        <limit effort="1000" lower="-0.8757" upper="0.8757" velocity="2.0" />
        <mimic joint="finger_joint" multiplier="-1" offset="0" />
    </joint>
    <joint name="right_inner_finger_joint" type="revolute">
        <origin rpy="-0.725 0 0" xyz="0 0.0817554015893473 -0.0282203446692936" />
        <parent link="right_outer_finger" />
        <child link="right_inner_finger" />
        <axis xyz="1 0 0" />
        <limit effort="1000" lower="-0.8757" upper="0.8757" velocity="2.0" />
        <mimic joint="finger_joint" multiplier="1" offset="0" />
    </joint>
    <joint name="right_inner_finger_pad_joint" type="fixed">
        <origin rpy="0 0 0" xyz="0 0.0457554015893473 -0.0272203446692936" />
        <parent link="right_inner_finger" />
        <child link="right_inner_finger_pad" />
        <axis xyz="0 0 1" />
    </joint>
    <transmission name="finger_joint_trans">
        <type>transmission_interface/SimpleTransmission</type>
        <joint name="finger_joint">
            <hardwareInterface>PositionJointInterface</hardwareInterface>
        </joint>
        <actuator name="finger_joint_motor">
            <mechanicalReduction>1</mechanicalReduction>
        </actuator>
    </transmission>
    <gazebo>
        <!-- loading plugin: mimic joints works in gazebo now-->
        <plugin filename="libroboticsgroup_gazebo_mimic_joint_plugin.so" name="mimic_robotiq_140_4">
            <joint>finger_joint</joint>
            <mimicJoint>right_outer_knuckle_joint</mimicJoint>
            <!--<multiplier>-1.0</multiplier>-->
            <!--<offset>0.0</offset>-->
        </plugin>
        <plugin filename="libroboticsgroup_gazebo_mimic_joint_plugin.so" name="mimic_robotiq_140_2">
            <joint>finger_joint</joint>
            <mimicJoint>left_inner_finger_joint</mimicJoint>
            <!--<multiplier>1.0</multiplier>-->
            <!--<offset>0.0</offset>-->
        </plugin>
        <plugin filename="libroboticsgroup_gazebo_mimic_joint_plugin.so" name="mimic_robotiq_140_5">
            <joint>finger_joint</joint>
            <mimicJoint>right_inner_finger_joint</mimicJoint>
            <!--<multiplier>1.0</multiplier>-->
            <!--<offset>0.0</offset>-->
        </plugin>
        <plugin filename="libroboticsgroup_gazebo_mimic_joint_plugin.so" name="mimic_robotiq_140_3">
            <joint>finger_joint</joint>
            <mimicJoint>left_inner_knuckle_joint</mimicJoint>
            <!--<multiplier>-1.0</multiplier>-->
            <!--<offset>0.0</offset>-->
        </plugin>
        <plugin filename="libroboticsgroup_gazebo_mimic_joint_plugin.so" name="mimic_robotiq_140_5">
            <joint>finger_joint</joint>
            <mimicJoint>right_inner_knuckle_joint</mimicJoint>
            <!--<multiplier>-1.0</multiplier>-->
            <!--<offset>0.0</offset>-->
        </plugin>
    </gazebo>
    <link name="upper_chasis">
        
<inertial>
            <origin rpy="0 0 0" xyz="0.408010034067037 0.523436425874833 0.310459511796759" />
            <mass value="0.830786236359305" />
            <inertia ixx="0.0113561959346229" ixy="-1.77137015581408E-06" ixz="-1.92392161060582E-12" iyy="0.00307752453202283" iyz="-2.16245929932274E-11" izz="0.00841950781307632" />
        </inertial>

        <visual>
            <origin rpy="0 0 0" xyz="0 0 0" />
            <geometry>
                <mesh filename="package://v5_asm/meshes/upper_chasis.STL" />
            </geometry>
            <material name="">
                <color rgba="0.792156862745098 0.819607843137255 0.933333333333333 1" />
            </material>
        </visual>
        <collision>
            <origin rpy="0 0 0" xyz="0 0 0" />
            <geometry>
                <mesh filename="package://v5_asm/meshes/upper_chasis.STL" />
            </geometry>
        </collision>
    </link>
    <joint name="upper_chasis" type="fixed">
        <origin rpy="1.5708 0 1.5708" xyz="-0.07828 -0.90265 0.78248" />
        <parent link="base_link_main" />
        <child link="upper_chasis" />
        <axis xyz="0 0 0" />
    </joint>
    <link name="kinect">
        
<inertial>
            <origin rpy="0 0 0" xyz="2.85546254141789E-06 0.00442617876381557 -0.0296652165432638" />
            <mass value="2.43875456249446" />
            <inertia ixx="0.00366777685200428" ixy="3.65666914100067E-08" ixz="-4.13408382742863E-07" iyy="0.0053508686708892" iyz="0.000216031980389351" izz="0.00205613161528836" />
        </inertial>

        <visual>
            <origin rpy="0 0 0" xyz="0 0 0" />
            <geometry>
                <mesh filename="package://v5_asm/meshes/kinect.dae" />
            </geometry>
            <material name="">
                <color rgba="0.941176470588235 0.941176470588235 0.941176470588235 1" />
            </material>
        </visual>
        <collision>
            <origin rpy="0 0 0" xyz="0 0 0" />
            <geometry>
                <mesh filename="package://v5_asm/meshes/kinect.dae" />
            </geometry>
        </collision>
    </link>
    <joint name="kinect" type="fixed">
        <!-- .31779 -->
        <origin rpy="-1.57079632679 -1.5708 0" xyz="0.378055 0.80334 0.30488" />
        <parent link="upper_chasis" />
        <child link="kinect" />
        <axis xyz="0 0 0" />
    </joint>
    <link name="lidar">
        
<inertial>
            <origin rpy="0 0 0" xyz="0.000294783332731696 0.0357745252112349 -2.58234201516716E-06" />
            <mass value="0.585082164914895" />
            <inertia ixx="0.00062906696678346" ixy="-6.8476888066688E-08" ixz="-1.14106053435051E-10" iyy="0.000749251783736662" iyz="-5.004876230364E-08" izz="0.000630263932043022" />
        </inertial>

        <visual>
            <origin rpy="0 0 0" xyz="0 0 0" />
            <geometry>
                <mesh filename="package://v5_asm/meshes/lidar.dae" />
            </geometry>
            <material name="">
                <color rgba="0.792156862745098 0.819607843137255 0.933333333333333 1" />
            </material>
        </visual>
        <collision>
            <origin rpy="0 0 0" xyz="0 0 0" />
            <geometry>
                <mesh filename="package://v5_asm/meshes/lidar.dae" />
            </geometry>
        </collision>
    </link>
    <joint name="lidar" type="fixed">
        <origin rpy="1.57079632679 0 0" xyz="0.40469 0.763 0.30488" />
        <parent link="upper_chasis" />
        <child link="lidar" />
        <axis xyz="0 0 0" />
    </joint>
    <link name="monitor">
        
<inertial>
            <origin rpy="0 0 0" xyz="-9.44272438019311E-13 0.0100274135784167 1.28586030712086E-12" />
            <mass value="1.77239075139848" />
            <inertia ixx="0.0081743729118215" ixy="-2.82200542311203E-12" ixz="4.5362584792376E-17" iyy="0.0290517648183889" iyz="-6.23620652586998E-17" izz="0.0209962115185463" />
        </inertial>

        <visual>
            <origin rpy="0 0 0" xyz="0 0 0" />
            <geometry>
                <mesh filename="package://v5_asm/meshes/monitor.dae" />
            </geometry>
            <material name="">
                <color rgba="0.647058823529412 0.619607843137255 0.6 1" />
            </material>
        </visual>
        <collision>
            <origin rpy="0 0 0" xyz="0 0 0" />
            <geometry>
                <mesh filename="package://v5_asm/meshes/monitor.dae" />
            </geometry>
        </collision>
    </link>
    <joint name="monitor" type="fixed">
        <origin rpy="0 1.5708 0" xyz="0.4177 0.55518 0.3106" />
        <parent link="upper_chasis" />
        <child link="monitor" />
        <axis xyz="0 0 0" />
    </joint>
    <link name="hokuyo">
        
<inertial>
            <origin rpy="0 0 0" xyz="0.133584074211728 0.202324368680826 0.204105336507967" />
            <mass value="0.652167585839582" />
            <inertia ixx="0.00157050335763022" ixy="1.74853977399192E-06" ixz="3.70456316395289E-08" iyy="0.00157786080287871" iyz="-1.22184572203833E-07" izz="0.000194017970807751" />
        </inertial>

        <visual>
            <origin rpy="0 0 0" xyz="0 0 0" />
            <geometry>
                <mesh filename="package://v5_asm/meshes/hokuyo.dae" />
            </geometry>
            <material name="">
                <color rgba="0.752941176470588 0.752941176470588 0.752941176470588 1" />
            </material>
        </visual>
        <collision>
            <origin rpy="0 0 0" xyz="0 0 0" />
            <geometry>
                <mesh filename="package://v5_asm/meshes/hokuyo.dae" />
            </geometry>
        </collision>
    </link>
    <joint name="base_to_hokuyo" type="fixed">
        <origin rpy="0 3.14159265 1.5707963267949" xyz="0.02746682844 -0.977022583965 0.73431985122" />
        <parent link="base_link_main" />
        <child link="hokuyo" />
        <axis xyz="0 0 0" />
    </joint>
    <transmission name="trans_shoulder_pan_joint">
        <type>transmission_interface/SimpleTransmission</type>
        <joint name="shoulder_pan_joint">
            <hardwareInterface>hardware_interface/EffortJointInterface</hardwareInterface>
        </joint>
        <actuator name="shoulder_pan_joint_motor">
            <hardwareInterface>hardware_interface/EffortJointInterface</hardwareInterface>
            <mechanicalReduction>1</mechanicalReduction>
        </actuator>
    </transmission>
    <transmission name="trans_shoulder_lift_joint">
        <type>transmission_interface/SimpleTransmission</type>
        <joint name="shoulder_lift_joint">
            <hardwareInterface>hardware_interface/EffortJointInterface</hardwareInterface>
        </joint>
        <actuator name="shoulder_lift_joint_motor">
            <hardwareInterface>hardware_interface/EffortJointInterface</hardwareInterface>
            <mechanicalReduction>1</mechanicalReduction>
        </actuator>
    </transmission>
    <transmission name="trans_elbow_joint">
        <type>transmission_interface/SimpleTransmission</type>
        <joint name="elbow_joint">
            <hardwareInterface>hardware_interface/EffortJointInterface</hardwareInterface>
        </joint>
        <actuator name="elbow_joint_motor">
            <hardwareInterface>hardware_interface/EffortJointInterface</hardwareInterface>
            <mechanicalReduction>1</mechanicalReduction>
        </actuator>
    </transmission>
    <transmission name="trans_wrist_1_joint">
        <type>transmission_interface/SimpleTransmission</type>
        <joint name="wrist_1_joint">
            <hardwareInterface>hardware_interface/EffortJointInterface</hardwareInterface>
        </joint>
        <actuator name="wrist_1_joint_motor">
            <hardwareInterface>hardware_interface/EffortJointInterface</hardwareInterface>
            <mechanicalReduction>1</mechanicalReduction>
        </actuator>
    </transmission>
    <transmission name="trans_wrist_2_joint">
        <type>transmission_interface/SimpleTransmission</type>
        <joint name="wrist_2_joint">
            <hardwareInterface>hardware_interface/EffortJointInterface</hardwareInterface>
        </joint>
        <actuator name="wrist_2_joint_motor">
            <hardwareInterface>hardware_interface/EffortJointInterface</hardwareInterface>
            <mechanicalReduction>1</mechanicalReduction>
        </actuator>
    </transmission>
    <transmission name="trans_wrist_3_joint">
        <type>transmission_interface/SimpleTransmission</type>
        <joint name="wrist_3_joint">
            <hardwareInterface>hardware_interface/EffortJointInterface</hardwareInterface>
        </joint>
        <actuator name="wrist_3_joint_motor">
            <hardwareInterface>hardware_interface/EffortJointInterface</hardwareInterface>
            <mechanicalReduction>1</mechanicalReduction>
        </actuator>
    </transmission>
    <transmission name="trans_left_wheel">
        <type>transmission_interface/SimpleTransmission</type>
        <joint name="left_wheel">
            <hardwareInterface>hardware_interface/EffortJointInterface</hardwareInterface>
        </joint>
        <actuator name="left_wheel_motor">
            <hardwareInterface>hardware_interface/EffortJointInterface</hardwareInterface>
            <mechanicalReduction>1</mechanicalReduction>
        </actuator>
    </transmission>
    <transmission name="trans_right_wheel">
        <type>transmission_interface/SimpleTransmission</type>
        <joint name="right_wheel">
            <hardwareInterface>hardware_interface/EffortJointInterface</hardwareInterface>
        </joint>
        <actuator name="right_wheel_motor">
            <hardwareInterface>hardware_interface/EffortJointInterface</hardwareInterface>
            <mechanicalReduction>1</mechanicalReduction>
        </actuator>
    </transmission>
    <transmission name="trans_rear_caster_swivel">
        <type>transmission_interface/SimpleTransmission</type>
        <joint name="rear_caster_swivel">
            <hardwareInterface>hardware_interface/EffortJointInterface</hardwareInterface>
        </joint>
        <actuator name="rear_caster_swivel_motor">
            <hardwareInterface>hardware_interface/EffortJointInterface</hardwareInterface>
            <mechanicalReduction>1</mechanicalReduction>
        </actuator>
    </transmission>
    <transmission name="trans_rear_caster_wheel">
        <type>transmission_interface/SimpleTransmission</type>
        <joint name="rear_caster_wheel">
            <hardwareInterface>hardware_interface/EffortJointInterface</hardwareInterface>
        </joint>
        <actuator name="rear_caster_wheel_motor">
            <hardwareInterface>hardware_interface/EffortJointInterface</hardwareInterface>
            <mechanicalReduction>1</mechanicalReduction>
        </actuator>
    </transmission>
    <transmission name="trans_front_caster_swivel">
        <type>transmission_interface/SimpleTransmission</type>
        <joint name="front_caster_swivel">
            <hardwareInterface>hardware_interface/EffortJointInterface</hardwareInterface>
        </joint>
        <actuator name="front_caster_swivel_motor">
            <hardwareInterface>hardware_interface/EffortJointInterface</hardwareInterface>
            <mechanicalReduction>1</mechanicalReduction>
        </actuator>
    </transmission>
    <transmission name="trans_front_caster_wheel">
        <type>transmission_interface/SimpleTransmission</type>
        <joint name="front_caster_wheel">
            <hardwareInterface>hardware_interface/EffortJointInterface</hardwareInterface>
        </joint>
        <actuator name="front_caster_wheel_motor">
            <hardwareInterface>hardware_interface/EffortJointInterface</hardwareInterface>
            <mechanicalReduction>1</mechanicalReduction>
        </actuator>
    </transmission>
    <transmission name="trans_finger_joint">
        <type>transmission_interface/SimpleTransmission</type>
        <joint name="finger_joint">
            <hardwareInterface>hardware_interface/EffortJointInterface</hardwareInterface>
        </joint>
        <actuator name="finger_joint_motor">
            <hardwareInterface>hardware_interface/EffortJointInterface</hardwareInterface>
            <mechanicalReduction>1</mechanicalReduction>
        </actuator>
    </transmission>
    <transmission name="trans_left_inner_knuckle_joint">
        <type>transmission_interface/SimpleTransmission</type>
        <joint name="left_inner_knuckle_joint">
            <hardwareInterface>hardware_interface/EffortJointInterface</hardwareInterface>
        </joint>
        <actuator name="left_inner_knuckle_joint_motor">
            <hardwareInterface>hardware_interface/EffortJointInterface</hardwareInterface>
            <mechanicalReduction>1</mechanicalReduction>
        </actuator>
    </transmission>
    <transmission name="trans_left_inner_finger_joint">
        <type>transmission_interface/SimpleTransmission</type>
        <joint name="left_inner_finger_joint">
            <hardwareInterface>hardware_interface/EffortJointInterface</hardwareInterface>
        </joint>
        <actuator name="left_inner_finger_joint_motor">
            <hardwareInterface>hardware_interface/EffortJointInterface</hardwareInterface>
            <mechanicalReduction>1</mechanicalReduction>
        </actuator>
    </transmission>
    <transmission name="trans_right_outer_knuckle_joint">
        <type>transmission_interface/SimpleTransmission</type>
        <joint name="right_outer_knuckle_joint">
            <hardwareInterface>hardware_interface/EffortJointInterface</hardwareInterface>
        </joint>
        <actuator name="right_outer_knuckle_joint_motor">
            <hardwareInterface>hardware_interface/EffortJointInterface</hardwareInterface>
            <mechanicalReduction>1</mechanicalReduction>
        </actuator>
    </transmission>
    <transmission name="trans_right_inner_knuckle_joint">
        <type>transmission_interface/SimpleTransmission</type>
        <joint name="right_inner_knuckle_joint">
            <hardwareInterface>hardware_interface/EffortJointInterface</hardwareInterface>
        </joint>
        <actuator name="right_inner_knuckle_joint_motor">
            <hardwareInterface>hardware_interface/EffortJointInterface</hardwareInterface>
            <mechanicalReduction>1</mechanicalReduction>
        </actuator>
    </transmission>
    <transmission name="trans_right_inner_finger_joint">
        <type>transmission_interface/SimpleTransmission</type>
        <joint name="right_inner_finger_joint">
            <hardwareInterface>hardware_interface/EffortJointInterface</hardwareInterface>
        </joint>
        <actuator name="right_inner_finger_joint_motor">
            <hardwareInterface>hardware_interface/EffortJointInterface</hardwareInterface>
            <mechanicalReduction>1</mechanicalReduction>
        </actuator>
    </transmission>
    <gazebo>
        <plugin name="gazebo_ros_control" filename="libgazebo_ros_control.so">
            <robotNamespace>/</robotNamespace>
        </plugin>
    </gazebo>
</robot>

<transmission name="shoulder_pan_trans">
        <type>transmission_interface/SimpleTransmission</type>
        <joint name="shoulder_pan_joint">
            <hardwareInterface>hardware_interface/PositionJointInterface</hardwareInterface>
        </joint>
        <actuator name="shoulder_pan_motor">
            <mechanicalReduction>1</mechanicalReduction>
        </actuator>
    </transmission>
    <transmission name="shoulder_lift_trans">
        <type>transmission_interface/SimpleTransmission</type>
        <joint name="shoulder_lift_joint">
            <hardwareInterface>hardware_interface/PositionJointInterface</hardwareInterface>
        </joint>
        <actuator name="shoulder_lift_motor">
            <mechanicalReduction>1</mechanicalReduction>
        </actuator>
    </transmission>
    <transmission name="elbow_trans">
        <type>transmission_interface/SimpleTransmission</type>
        <joint name="elbow_joint">
            <hardwareInterface>hardware_interface/PositionJointInterface</hardwareInterface>
        </joint>
        <actuator name="elbow_motor">
            <mechanicalReduction>1</mechanicalReduction>
        </actuator>
    </transmission>
    <transmission name="wrist_1_trans">
        <type>transmission_interface/SimpleTransmission</type>
        <joint name="wrist_1_joint">
            <hardwareInterface>hardware_interface/PositionJointInterface</hardwareInterface>
        </joint>
        <actuator name="wrist_1_motor">
            <mechanicalReduction>1</mechanicalReduction>
        </actuator>
    </transmission>
    <transmission name="wrist_2_trans">
        <type>transmission_interface/SimpleTransmission</type>
        <joint name="wrist_2_joint">
            <hardwareInterface>hardware_interface/PositionJointInterface</hardwareInterface>
        </joint>
        <actuator name="wrist_2_motor">
            <mechanicalReduction>1</mechanicalReduction>
        </actuator>
    </transmission>
    <transmission name="wrist_3_trans">
        <type>transmission_interface/SimpleTransmission</type>
        <joint name="wrist_3_joint">
            <hardwareInterface>hardware_interface/PositionJointInterface</hardwareInterface>
        </joint>
        <actuator name="wrist_3_motor">
            <mechanicalReduction>1</mechanicalReduction>
        </actuator>
    </transmission>
    <gazebo reference="shoulder_link">
        <selfCollide>true</selfCollide>
    </gazebo>
    <gazebo reference="upper_arm_link">
        <selfCollide>true</selfCollide>
    </gazebo>
    <gazebo reference="forearm_link">
        <selfCollide>true</selfCollide>
    </gazebo>
    <gazebo reference="wrist_1_link">
        <selfCollide>true</selfCollide>
    </gazebo>
    <gazebo reference="wrist_3_link">
        <selfCollide>true</selfCollide>
    </gazebo>
    <gazebo reference="wrist_2_link">
        <selfCollide>true</selfCollide>
    </gazebo>
    <gazebo reference="ee_link">
        <selfCollide>true</selfCollide>
    </gazebo>
    <!-- ROS base_link to UR 'Base' Coordinates transform -->
    <link name="base" />
    <joint name="base_link-base_fixed_joint" type="fixed">
        <!-- NOTE: this rotation is only needed as long as base_link itself is
                 not corrected wrt the real robot (ie: rotated over 180
                 degrees)
      -->
        <origin rpy="0 0 -3.14159265359" xyz="0 0 0" />
        <parent link="base_link" />
        <child link="base" />
    </joint>
    <!-- Frame coincident with all-zeros TCP on UR controller -->
    <link name="tool0" />
    <joint name="wrist_3_link-tool0_fixed_joint" type="fixed">
        <origin rpy="-1.57079632679 0 0" xyz="0 0.0823 0" />
        <parent link="wrist_3_link" />
        <child link="tool0" />
    </joint>
    <link name="base_link_main">
        <inertial>
            <origin rpy="-3.14159265359 0 0" xyz="0 0 0" />
            <mass value="20.4660866954057" />
            <inertia ixx="0.193568038684775" ixy="0.00548623614276343" ixz="-6.15228083843436E-05" iyy="0.108859012808764" iyz="-0.00384844545395753" izz="0.229327239703698" />
        </inertial>
        <visual>
            <origin rpy="3.14159265359 0 0" xyz="0.211886378 -0.81046675318 .51736994677" />
            <geometry>
                <mesh filename="package://v5_asm/meshes/base_link.dae" />
            </geometry>
            <material name="">
                <color rgba="0.752941176470588 0.752941176470588 0.752941176470588 1" />
            </material>
        </visual>
        <collision>
            <origin rpy="3.14159265359 0 0" xyz="0.211886378 -0.81046675318 .51736994677" />
            <geometry>
                <mesh filename="package://v5_asm/meshes/base_link_main.dae" />
            </geometry>
        </collision>
    </link>
    <joint name="world_to_base" type="fixed">
        <parent link="world" />
        <child link="base_link_main" />
        <origin rpy="0.0 0.0 0.0" xyz="0.0 0.0 0.0" />
    </joint>
    <link name="arm_stand">
        <inertial>
            <origin rpy="0 0 0" xyz="-0.0449002179804069 -0.00120158576170751 -0.0786427433397576" />
            <mass value="1.50525286307822" />
            <inertia ixx="0.00548888032967621" ixy="1.929980925743E-05" ixz="-0.00180882087465193" iyy="0.00662090700121496" iyz="6.80641116194522E-06" izz="0.00455713436329697" />
        </inertial>
        <visual>
            <origin rpy="0 0 0" xyz="0 0 0" />
            <geometry>
                <mesh filename="package://v5_asm/meshes/arm_stand.dae" />
            </geometry>
            <material name="">
                <color rgba="0.792156862745098 0.819607843137255 0.933333333333333 1" />
            </material>
        </visual>
        <collision>
            <origin rpy="0 0 0" xyz="0 0 0" />
            <geometry>
                <mesh filename="package://v5_asm/meshes/arm_stand.dae" />
            </geometry>
        </collision>
    </link>
    <joint name="arm_stand" type="fixed">
        <origin rpy="0 -0.5236 1.5708" xyz="0.17434 -0.98064 0.86287" />
        <parent link="base_link_main" />
        <child link="arm_stand" />
        <axis xyz="0.5 0 0.86603" />
    </joint>
    <joint name="stand_to_arm" type="fixed">
        <origin rpy="0 0 0" xyz="0 0 0.016" />
        <parent link="arm_stand" />
        <child link="base_link" />
        <axis xyz="0.86603 -0.022933 0.49947" />
    </joint>
    <!-- inches -->
    <!-- inches -->
    <!-- colors -->
    <material name="light_grey">
        <color rgba="0.7 0.7 0.7 1" />
    </material>
    <material name="dark_grey">
        <color rgba="0.5 0.5 0.5 1" />
    </material>
    <material name="black">
        <color rgba="0 0 0 1" />
    </material>
    <material name="almost_black">
        <color rgba="0.02 0.02 0.02 1" />
    </material>
    <!-- <gazebo> -->
    <!--   <plugin name="gazebo_ros_control" filename="libgazebo_ros_control.so"> -->
    <!--     <robotNamespace>/</robotNamespace> -->
    <!--   </plugin> -->
    <!-- </gazebo> -->
    <!-- Base footprint is the center of the robot's chassis between the motors projected on the ground change base_link_2 to base_link
    <link name="base_footprint"/-->
    <!-- base_link is another name for base_footprint, Another name for the ground projection that is used in all segbot codebase-->
    <link name="base_link_2" />
    <joint name="base_footprint_joint" type="fixed">
        <origin rpy="0 0 1.57079632679" xyz="0.232104567 -0.81046675318 0.24551258" />
        <parent link="base_link_main" />
        <child link="base_link_2" />
    </joint>
    <joint name="base_chassis_joint" type="fixed">
        <origin rpy="0 0 0" xyz="0 0 0.15801795" />
        <parent link="base_link_2" />
        <child link="base_chassis_link" />
    </joint>
    <link name="base_chassis_link">
        <visual>
            <geometry>
                <mesh filename="package://segway_description/meshes/visual/std_gearbox_chassis.dae" />
            </geometry>
        </visual>
    </link>
    <link name="inertial_collision_link">
        <inertial>
            <mass value="36.914402" />
            <origin xyz="-0.043407 0.000037 0.060079" />
            <inertia ixx="1.182744" ixy="0.017957" ixz="-0.077476" iyx="0.017957" iyy="0.538664" iyz="0.000018" izx="-0.077476" izy="0.000018" izz="1.240229" />
        </inertial>
        <collision>
            <geometry>
                <mesh filename="package://segway_description/meshes/collision/RMP210_chassis_collision.stl" />
            </geometry>
        </collision>
    </link>
    <joint name="inertial_collision_joint" type="fixed">
        <parent link="base_chassis_link" />
        <child link="inertial_collision_link" />
    </joint>
    <joint name="left_spacer_joint" type="fixed">
        <origin rpy="0 0 0" xyz="0 0.19582 0.00665015" />
        <parent link="base_chassis_link" />
        <child link="left_spacer_link" />
    </joint>
    <link name="left_spacer_link">
        <visual>
            <geometry>
                <mesh filename="package://segway_description/meshes/visual/single_spacer.dae" />
            </geometry>
        </visual>
    </link>
    <joint name="right_spacer_joint" type="fixed">
        <origin rpy="0 0 3.14159265359" xyz="0 -0.19582 0.00665015" />
        <parent link="base_chassis_link" />
        <child link="right_spacer_link" />
    </joint>
    <link name="right_spacer_link">
        <visual>
            <geometry>
                <mesh filename="package://segway_description/meshes/visual/single_spacer.dae" />
            </geometry>
        </visual>
    </link>
    <joint name="mcu_1_battery_joint" type="fixed">
        <origin rpy="0 0 0" xyz="-0.09298 0 0" />
        <parent link="base_chassis_link" />
        <child link="mcu_1_battery_link" />
    </joint>
    <link name="mcu_1_battery_link">
        <visual>
            <geometry>
                <mesh filename="package://segway_description/meshes/visual/battery.dae" />
            </geometry>
        </visual>
    </link>
    <joint name="aux_battery_joint" type="fixed">
        <origin rpy="0 0 3.14159265359" xyz="0.09298 0 0" />
        <parent link="base_chassis_link" />
        <child link="aux_battery_link" />
    </joint>
    <link name="aux_battery_link">
        <visual>
            <geometry>
                <mesh filename="package://segway_description/meshes/visual/battery.dae" />
            </geometry>
        </visual>
    </link>
    <link name="left_wheel_link">
        <inertial>
            <mass value="4.195729" />
            <origin xyz="0 0 0" />
            <inertia ixx="0.063680" ixy="0.000000" ixz="0.000000" iyx="0.000000" iyy="0.121410" iyz="0.000000" izx="0.000000" izy="0.000000" izz="0.063680" />
        </inertial>
        <visual>
            <origin rpy="0 0 0.0" xyz="0 0 0" />
            <geometry>
                <mesh filename="package://segway_description/meshes/visual/i2_wheel.dae" />
            </geometry>
        </visual>
        <collision>
            <origin rpy="1.5707963268 0 0" xyz="0 0 0" />
            <geometry>
                <cylinder length="0.092249" radius="0.2405681" />
            </geometry>
        </collision>
    </link>
    <gazebo reference="left_wheel_link">
        <mu1 value="10.0" />
        <mu2 value="10.0" />
        <kp value="10000000.0" />
        <kd value="10.0" />
        <fdir1 value="1 0 0" />
        <minDepth>0.003</minDepth>
    </gazebo>
    <joint name="left_wheel" type="continuous">
        <parent link="base_chassis_link" />
        <child link="left_wheel_link" />
        <origin rpy="0 0 0" xyz="0 0.2395555 0.08255015" />
        <axis rpy="0 0 0" xyz="0 1 0" />
    </joint>
    <transmission name="left_wheel_trans" type="SimpleTransmission">
        <type>transmission_interface/SimpleTransmission</type>
        <actuator name="left_wheel_motor">
            <mechanicalReduction>1</mechanicalReduction>
        </actuator>
        <joint name="left_wheel">
            <hardwareInterface>VelocityJointInterface</hardwareInterface>
        </joint>
    </transmission>
    <link name="right_wheel_link">
        <inertial>
            <mass value="4.195729" />
            <origin xyz="0 0 0" />
            <inertia ixx="0.063680" ixy="0.000000" ixz="0.000000" iyx="0.000000" iyy="0.121410" iyz="0.000000" izx="0.000000" izy="0.000000" izz="0.063680" />
        </inertial>
        <visual>
            <origin rpy="0 0 3.14159265359" xyz="0 0 0" />
            <geometry>
                <mesh filename="package://segway_description/meshes/visual/i2_wheel.dae" />
            </geometry>
        </visual>
        <collision>
            <origin rpy="1.5707963268 0 0" xyz="0 0 0" />
            <geometry>
                <cylinder length="0.092249" radius="0.2405681" />
            </geometry>
        </collision>
    </link>
    <gazebo reference="right_wheel_link">
        <mu1 value="10.0" />
        <mu2 value="10.0" />
        <kp value="10000000.0" />
        <kd value="10.0" />
        <fdir1 value="1 0 0" />
        <minDepth>0.003</minDepth>
    </gazebo>
    <joint name="right_wheel" type="continuous">
        <parent link="base_chassis_link" />
        <child link="right_wheel_link" />
        <origin rpy="0 0 0" xyz="0 -0.2395555 0.08255015" />
        <axis rpy="0 0 0" xyz="0 1 0" />
    </joint>
    <transmission name="right_wheel_trans" type="SimpleTransmission">
        <type>transmission_interface/SimpleTransmission</type>
        <actuator name="right_wheel_motor">
            <mechanicalReduction>1</mechanicalReduction>
        </actuator>
        <joint name="right_wheel">
            <hardwareInterface>VelocityJointInterface</hardwareInterface>
        </joint>
    </transmission>
    <joint name="rear_caster_plate_joint" type="fixed">
        <origin rpy="0 0 0" xyz="-0.31472057 0 0.02425235" />
        <parent link="base_chassis_link" />
        <child link="rear_caster_plate_link" />
    </joint>
    <link name="rear_caster_plate_link">
        <inertial>
            <mass value="4.487241" />
            <origin xyz="0.027375 0 0.016101" />
            <inertia ixx="0.070527" ixy="0.000000" ixz="-0.001013" iyx="0.000000" iyy="0.010678" iyz="0.000000" izx="-0.001013" izy="0.000000" izz="0.078313" />
        </inertial>
        <visual>
            <geometry>
                <mesh filename="package://segway_description/meshes/visual/caster_plate.dae" />
            </geometry>
        </visual>
        <collision>
            <geometry>
                <mesh filename="package://segway_description/meshes/collision/caster_plate_collision.stl" />
            </geometry>
        </collision>
    </link>
    <link name="rear_caster_swivel_link">
        <inertial>
            <mass value="0.579519" />
            <origin xyz="-0.020596 0.000280 -0.055367" />
            <inertia ixx="0.001361" ixy="-0.000003" ixz="0.000347" iyx="-0.000003" iyy="0.001287" iyz="-0.000010" izx="0.000347" izy="-0.000010" izz="0.000632" />
        </inertial>
        <visual>
            <geometry>
                <mesh filename="package://segway_description/meshes/visual/caster_bracket.dae" />
            </geometry>
        </visual>
        <collision>
            <geometry>
                <mesh filename="package://segway_description/meshes/collision/caster_bracket_collision.stl" />
            </geometry>
        </collision>
    </link>
    <gazebo reference="rear_caster_swivel_link">
        <mu1 value="100.0" />
        <mu2 value="100.0" />
        <kp value="10000000.0" />
        <kd value="1.0" />
    </gazebo>
    <joint name="rear_caster_swivel" type="continuous">
        <parent link="rear_caster_plate_link" />
        <child link="rear_caster_swivel_link" />
        <!--xacro:insert_block name="joint_pose"/-->
        <axis xyz="0 0 1" />
        <anchor xyz="0 0 0" />
        <limit effort="0.0" velocity="1000" />
        <dynamics damping="0.7" />
    </joint>
    <transmission name="rear_caster_swivel_trans" type="SimpleTransmission">
        <type>transmission_interface/SimpleTransmission</type>
        <joint name="rear_caster_swivel">
            <hardwareInterface>EffortJointInterface</hardwareInterface>
        </joint>
        <actuator name="rear_caster_swivel_motor">
            <hardwareInterface>EffortJointInterface</hardwareInterface>
            <mechanicalReduction>1</mechanicalReduction>
        </actuator>
    </transmission>
    <link name="rear_caster_wheel_link">
        <inertial>
            <mass value="1.25" />
            <origin xyz="0 0 0" />
            <inertia ixx="0.001442" ixy="0.000000" ixz="0.000000" iyx="0.000000" iyy="0.002493" iyz="0.000000" izx="0.000000" izy="0.000000" izz="0.001442" />
        </inertial>
        <visual>
            <geometry>
                <mesh filename="package://segway_description/meshes/visual/caster_wheel.dae" />
            </geometry>
        </visual>
        <collision>
            <origin rpy="1.5707963268 0 0" xyz="0 0 0" />
            <geometry>
                <cylinder length="0.050" radius="0.0762" />
            </geometry>
        </collision>
    </link>
    <gazebo reference="rear_caster_wheel_link">
        <mu1 value="100.0" />
        <mu2 value="100.0" />
        <kp value="10000000.0" />
        <kd value="10.0" />
        <fdir1 value="1 0 0" />
        <minDepth>0.003</minDepth>
    </gazebo>
    <joint name="rear_caster_wheel" type="continuous">
        <parent link="rear_caster_swivel_link" />
        <child link="rear_caster_wheel_link" />
        <origin rpy="0 0 0" xyz="-0.03782 0 -0.10608" />
        <axis xyz="0 1 0" />
        <anchor xyz="-0.03782 0 -0.10608" />
        <limit effort="0.0" velocity="1000" />
        <dynamics damping="0.2" />
    </joint>
    <transmission name="rear_caster_wheel_trans" type="SimpleTransmission">
        <type>transmission_interface/SimpleTransmission</type>
        <joint name="rear_caster_wheel">
            <hardwareInterface>EffortJointInterface</hardwareInterface>
        </joint>
        <actuator name="rear_caster_wheel_motor">
            <hardwareInterface>EffortJointInterface</hardwareInterface>
            <mechanicalReduction>1</mechanicalReduction>
        </actuator>
    </transmission>
    <joint name="front_caster_plate_joint" type="fixed">
        <origin rpy="0 0 3.14159265359" xyz="0.31472057 0 0.02425235" />
        <parent link="base_chassis_link" />
        <child link="front_caster_plate_link" />
    </joint>
    <link name="front_caster_plate_link">
        <inertial>
            <mass value="4.487241" />
            <origin xyz="0.027375 0 0.016101" />
            <inertia ixx="0.070527" ixy="0.000000" ixz="-0.001013" iyx="0.000000" iyy="0.010678" iyz="0.000000" izx="-0.001013" izy="0.000000" izz="0.078313" />
        </inertial>
        <visual>
            <geometry>
                <mesh filename="package://segway_description/meshes/visual/caster_plate.dae" />
            </geometry>
        </visual>
        <collision>
            <geometry>
                <mesh filename="package://segway_description/meshes/collision/caster_plate_collision.stl" />
            </geometry>
        </collision>
    </link>
    <link name="front_caster_swivel_link">
        <inertial>
            <mass value="0.579519" />
            <origin xyz="-0.020596 0.000280 -0.055367" />
            <inertia ixx="0.001361" ixy="-0.000003" ixz="0.000347" iyx="-0.000003" iyy="0.001287" iyz="-0.000010" izx="0.000347" izy="-0.000010" izz="0.000632" />
        </inertial>
        <visual>
            <geometry>
                <mesh filename="package://segway_description/meshes/visual/caster_bracket.dae" />
            </geometry>
        </visual>
        <collision>
            <geometry>
                <mesh filename="package://segway_description/meshes/collision/caster_bracket_collision.stl" />
            </geometry>
        </collision>
    </link>
    <gazebo reference="front_caster_swivel_link">
        <mu1 value="100.0" />
        <mu2 value="100.0" />
        <kp value="10000000.0" />
        <kd value="1.0" />
    </gazebo>
    <joint name="front_caster_swivel" type="continuous">
        <parent link="front_caster_plate_link" />
        <child link="front_caster_swivel_link" />
        <!--xacro:insert_block name="joint_pose"/-->
        <axis xyz="0 0 1" />
        <anchor xyz="0 0 0" />
        <limit effort="0.0" velocity="1000" />
        <dynamics damping="0.7" />
    </joint>
    <transmission name="front_caster_swivel_trans" type="SimpleTransmission">
        <type>transmission_interface/SimpleTransmission</type>
        <joint name="front_caster_swivel">
            <hardwareInterface>EffortJointInterface</hardwareInterface>
        </joint>
        <actuator name="front_caster_swivel_motor">
            <hardwareInterface>EffortJointInterface</hardwareInterface>
            <mechanicalReduction>1</mechanicalReduction>
        </actuator>
    </transmission>
    <link name="front_caster_wheel_link">
        <inertial>
            <mass value="1.25" />
            <origin xyz="0 0 0" />
            <inertia ixx="0.001442" ixy="0.000000" ixz="0.000000" iyx="0.000000" iyy="0.002493" iyz="0.000000" izx="0.000000" izy="0.000000" izz="0.001442" />
        </inertial>
        <visual>
            <geometry>
                <mesh filename="package://segway_description/meshes/visual/caster_wheel.dae" />
            </geometry>
        </visual>
        <collision>
            <origin rpy="1.5707963268 0 0" xyz="0 0 0" />
            <geometry>
                <cylinder length="0.050" radius="0.0762" />
            </geometry>
        </collision>
    </link>
    <gazebo reference="front_caster_wheel_link">
        <mu1 value="100.0" />
        <mu2 value="100.0" />
        <kp value="10000000.0" />
        <kd value="10.0" />
        <fdir1 value="1 0 0" />
        <minDepth>0.003</minDepth>
    </gazebo>
    <joint name="front_caster_wheel" type="continuous">
        <parent link="front_caster_swivel_link" />
        <child link="front_caster_wheel_link" />
        <origin rpy="0 0 0" xyz="-0.03782 0 -0.10608" />
        <axis xyz="0 1 0" />
        <anchor xyz="-0.03782 0 -0.10608" />
        <limit effort="0.0" velocity="1000" />
        <dynamics damping="0.2" />
    </joint>
    <transmission name="front_caster_wheel_trans" type="SimpleTransmission">
        <type>transmission_interface/SimpleTransmission</type>
        <joint name="front_caster_wheel">
            <hardwareInterface>EffortJointInterface</hardwareInterface>
        </joint>
        <actuator name="front_caster_wheel_motor">
            <hardwareInterface>EffortJointInterface</hardwareInterface>
            <mechanicalReduction>1</mechanicalReduction>
        </actuator>
    </transmission>
    <link name="robotiq_arg2f_base_link">
        <inertial>
            <origin rpy="0 0 0" xyz="8.625E-08 -4.6583E-06 0.03145" />
            <mass value="0.22652" />
            <inertia ixx="0.00020005" ixy="-4.2442E-10" ixz="-2.9069E-10" iyy="0.00017832" iyz="-3.4402E-08" izz="0.00013478" />
        </inertial>
        <visual>
            <origin rpy="0 0 0" xyz="0 0 0" />
            <geometry>
                <mesh filename="package://robotiq_2f_140_gripper_visualization/meshes/visual/robotiq_arg2f_base_link.stl" />
            </geometry>
            <material name="">
                <color rgba="0.1 0.1 0.1 1" />
            </material>
        </visual>
        <collision>
            <origin rpy="0 0 0" xyz="0 0 0" />
            <geometry>
                <mesh filename="package://robotiq_2f_140_gripper_visualization/meshes/collision/robotiq_arg2f_base_link.stl" />
            </geometry>
        </collision>
    </link>
    <joint name="arm_to_gripper" type="fixed">
        <parent link="wrist_3_link" />
        <child link="robotiq_arg2f_base_link" />
        <origin rpy="-1.57079632679 0 0" xyz="0 .0772199 0" />
    </joint>
    <link name="left_outer_knuckle">
        <inertial>
            <origin rpy="0 0 0" xyz="-0.000200000000003065 0.0199435877845359 0.0292245259211331" />
            <mass value="0.00853198276973456" />
            <inertia ixx="2.89328108496468E-06" ixy="-1.57935047237397E-19" ixz="-1.93980378593255E-19" iyy="1.86719750325683E-06" iyz="-1.21858577871576E-06" izz="1.21905238907251E-06" />
        </inertial>
        <visual>
            <origin rpy="0 0 0" xyz="0 0 0" />
            <geometry>
                <mesh filename="package://robotiq_2f_140_gripper_visualization/meshes/visual/robotiq_arg2f_140_outer_knuckle.stl" />
            </geometry>
            <material name="">
                <color rgba="0.792156862745098 0.819607843137255 0.933333333333333 1" />
            </material>
        </visual>
        <collision>
            <origin rpy="0 0 0" xyz="0 0 0" />
            <geometry>
                <mesh filename="package://robotiq_2f_140_gripper_visualization/meshes/collision/robotiq_arg2f_140_outer_knuckle.stl" />
            </geometry>
        </collision>
    </link>
    <link name="left_outer_finger">
        <inertial>
            <origin rpy="0 0 0" xyz="0.00030115855001899 0.0373907951953854 -0.0208027427000385" />
            <mass value="0.022614240507152" />
            <inertia ixx="1.52518312458174E-05" ixy="9.76583423954399E-10" ixz="-5.43838577022588E-10" iyy="6.17694243867776E-06" iyz="6.78636130740228E-06" izz="1.16494917907219E-05" />
        </inertial>
        <visual>
            <origin rpy="0 0 0" xyz="0 0 0" />
            <geometry>
                <mesh filename="package://robotiq_2f_140_gripper_visualization/meshes/visual/robotiq_arg2f_140_outer_finger.stl" />
            </geometry>
            <material name="">
                <color rgba="0.1 0.1 0.1 1" />
            </material>
        </visual>
        <collision>
            <origin rpy="0 0 0" xyz="0 0 0" />
            <geometry>
                <mesh filename="package://robotiq_2f_140_gripper_visualization/meshes/collision/robotiq_arg2f_140_outer_finger.stl" />
            </geometry>
        </collision>
    </link>
    <link name="left_inner_finger">
        <inertial>
            <origin rpy="0 0 0" xyz="0.000299999999999317 0.0160078233491243 -0.0136945669206257" />
            <mass value="0.0104003125914103" />
            <inertia ixx="2.71909453810972E-06" ixy="1.35402465472579E-21" ixz="-7.1817349065269E-22" iyy="7.69100314106116E-07" iyz="6.74715432769696E-07" izz="2.30315190420171E-06" />
        </inertial>
        <visual>
            <origin rpy="0 0 0" xyz="0 0 0" />
            <geometry>
                <mesh filename="package://robotiq_2f_140_gripper_visualization/meshes/visual/robotiq_arg2f_140_inner_finger.stl" />
            </geometry>
            <material name="">
                <color rgba="0.1 0.1 0.1 1" />
            </material>
        </visual>
        <collision>
            <origin rpy="0 0 0" xyz="0 0 0" />
            <geometry>
                <mesh filename="package://robotiq_2f_140_gripper_visualization/meshes/collision/robotiq_arg2f_140_inner_finger.stl" />
            </geometry>
        </collision>
    </link>
    <link name="left_inner_finger_pad">
        <visual>
            <origin rpy="0 0 0" xyz="0 0 0" />
            <geometry>
                <box size="0.027 0.065 0.0075" />
            </geometry>
            <material name="">
                <color rgba="0.9 0.9 0.9 1" />
            </material>
        </visual>
        <collision>
            <origin rpy="0 0 0" xyz="0 0 0" />
            <geometry>
                <box size="0.03 0.07 0.0075" />
            </geometry>
            <material name="">
                <color rgba="0.9 0.0 0.0 1" />
            </material>
        </collision>
        <inertial>
            <mass value="0.1" />
            <inertia ixx="0.03" iyy="0.03" izz="0.03" ixy="0.0" ixz="0.0" iyz="0.0" />
        </inertial>
    </link>
    <link name="left_inner_knuckle">
        <inertial>
            <origin rpy="0 0 0" xyz="0.000123011831763771 0.0507850843201817 0.00103968640075166" />
            <mass value="0.0271177346495152" />
            <inertia ixx="2.61910379223783E-05" ixy="-2.43616858946494E-07" ixz="-6.37789906117123E-09" iyy="2.8270243746167E-06" iyz="-5.37200748039765E-07" izz="2.83695868220296E-05" />
        </inertial>
        <visual>
            <origin rpy="0 0 0" xyz="0 0 0" />
            <geometry>
                <mesh filename="package://robotiq_2f_140_gripper_visualization/meshes/visual/robotiq_arg2f_140_inner_knuckle.stl" />
            </geometry>
            <material name="">
                <color rgba="0.1 0.1 0.1 1" />
            </material>
        </visual>
        <collision>
            <origin rpy="0 0 0" xyz="0 0 0" />
            <geometry>
                <mesh filename="package://robotiq_2f_140_gripper_visualization/meshes/collision/robotiq_arg2f_140_inner_knuckle.stl" />
            </geometry>
        </collision>
    </link>
    <link name="right_outer_knuckle">
        <inertial>
            <origin rpy="0 0 0" xyz="-0.000200000000003065 0.0199435877845359 0.0292245259211331" />
            <mass value="0.00853198276973456" />
            <inertia ixx="2.89328108496468E-06" ixy="-1.57935047237397E-19" ixz="-1.93980378593255E-19" iyy="1.86719750325683E-06" iyz="-1.21858577871576E-06" izz="1.21905238907251E-06" />
        </inertial>
        <visual>
            <origin rpy="0 0 0" xyz="0 0 0" />
            <geometry>
                <mesh filename="package://robotiq_2f_140_gripper_visualization/meshes/visual/robotiq_arg2f_140_outer_knuckle.stl" />
            </geometry>
            <material name="">
                <color rgba="0.792156862745098 0.819607843137255 0.933333333333333 1" />
            </material>
        </visual>
        <collision>
            <origin rpy="0 0 0" xyz="0 0 0" />
            <geometry>
                <mesh filename="package://robotiq_2f_140_gripper_visualization/meshes/collision/robotiq_arg2f_140_outer_knuckle.stl" />
            </geometry>
        </collision>
    </link>
    <link name="right_outer_finger">
        <inertial>
            <origin rpy="0 0 0" xyz="0.00030115855001899 0.0373907951953854 -0.0208027427000385" />
            <mass value="0.022614240507152" />
            <inertia ixx="1.52518312458174E-05" ixy="9.76583423954399E-10" ixz="-5.43838577022588E-10" iyy="6.17694243867776E-06" iyz="6.78636130740228E-06" izz="1.16494917907219E-05" />
        </inertial>
        <visual>
            <origin rpy="0 0 0" xyz="0 0 0" />
            <geometry>
                <mesh filename="package://robotiq_2f_140_gripper_visualization/meshes/visual/robotiq_arg2f_140_outer_finger.stl" />
            </geometry>
            <material name="">
                <color rgba="0.1 0.1 0.1 1" />
            </material>
        </visual>
        <collision>
            <origin rpy="0 0 0" xyz="0 0 0" />
            <geometry>
                <mesh filename="package://robotiq_2f_140_gripper_visualization/meshes/collision/robotiq_arg2f_140_outer_finger.stl" />
            </geometry>
        </collision>
    </link>
    <link name="right_inner_finger">
        <inertial>
            <origin rpy="0 0 0" xyz="0.000299999999999317 0.0160078233491243 -0.0136945669206257" />
            <mass value="0.0104003125914103" />
            <inertia ixx="2.71909453810972E-06" ixy="1.35402465472579E-21" ixz="-7.1817349065269E-22" iyy="7.69100314106116E-07" iyz="6.74715432769696E-07" izz="2.30315190420171E-06" />
        </inertial>
        <visual>
            <origin rpy="0 0 0" xyz="0 0 0" />
            <geometry>
                <mesh filename="package://robotiq_2f_140_gripper_visualization/meshes/visual/robotiq_arg2f_140_inner_finger.stl" />
            </geometry>
            <material name="">
                <color rgba="0.1 0.1 0.1 1" />
            </material>
        </visual>
        <collision>
            <origin rpy="0 0 0" xyz="0 0 0" />
            <geometry>
                <mesh filename="package://robotiq_2f_140_gripper_visualization/meshes/collision/robotiq_arg2f_140_inner_finger.stl" />
            </geometry>
        </collision>
    </link>
    <link name="right_inner_finger_pad">
        <visual>
            <origin rpy="0 0 0" xyz="0 0 0" />
            <geometry>
                <box size="0.027 0.065 0.0075" />
            </geometry>
            <material name="">
                <color rgba="0.9 0.9 0.9 1" />
            </material>
        </visual>
        <collision>
            <origin rpy="0 0 0" xyz="0 0 0" />
            <geometry>
                <box size="0.03 0.07 0.0075" />
            </geometry>
            <material name="">
                <color rgba="0.9 0.0 0.0 1" />
            </material>
        </collision>
        <inertial>
            <mass value="0.1" />
            <inertia ixx="0.03" iyy="0.03" izz="0.03" ixy="0.0" ixz="0.0" iyz="0.0" />
        </inertial>
    </link>
    <link name="right_inner_knuckle">
        <inertial>
            <origin rpy="0 0 0" xyz="0.000123011831763771 0.0507850843201817 0.00103968640075166" />
            <mass value="0.0271177346495152" />
            <inertia ixx="2.61910379223783E-05" ixy="-2.43616858946494E-07" ixz="-6.37789906117123E-09" iyy="2.8270243746167E-06" iyz="-5.37200748039765E-07" izz="2.83695868220296E-05" />
        </inertial>
        <visual>
            <origin rpy="0 0 0" xyz="0 0 0" />
            <geometry>
                <mesh filename="package://robotiq_2f_140_gripper_visualization/meshes/visual/robotiq_arg2f_140_inner_knuckle.stl" />
            </geometry>
            <material name="">
                <color rgba="0.1 0.1 0.1 1" />
            </material>
        </visual>
        <collision>
            <origin rpy="0 0 0" xyz="0 0 0" />
            <geometry>
                <mesh filename="package://robotiq_2f_140_gripper_visualization/meshes/collision/robotiq_arg2f_140_inner_knuckle.stl" />
            </geometry>
        </collision>
    </link>
    <joint name="finger_joint" type="revolute">
        <origin rpy="2.29579632679 0 0" xyz="0 -0.030601 0.054905" />
        <parent link="robotiq_arg2f_base_link" />
        <child link="left_outer_knuckle" />
        <axis xyz="-1 0 0" />
        <limit effort="1000" lower="0" upper="0.7" velocity="2.0" />
    </joint>
    <joint name="left_outer_finger_joint" type="fixed">
        <origin rpy="0 0 0" xyz="0 0.01821998610742 0.0260018192872234" />
        <parent link="left_outer_knuckle" />
        <child link="left_outer_finger" />
        <axis xyz="1 0 0" />
    </joint>
    <joint name="left_inner_knuckle_joint" type="revolute">
        <origin rpy="2.29579632679 0 0.0" xyz="0 -0.0127 0.06142" />
        <parent link="robotiq_arg2f_base_link" />
        <child link="left_inner_knuckle" />
        <axis xyz="1 0 0" />
        <limit effort="1000" lower="-0.8757" upper="0.8757" velocity="2.0" />
        <mimic joint="finger_joint" multiplier="-1" offset="0" />
    </joint>
    <joint name="left_inner_finger_joint" type="revolute">
        <origin rpy="-0.725 0 0" xyz="0 0.0817554015893473 -0.0282203446692936" />
        <parent link="left_outer_finger" />
        <child link="left_inner_finger" />
        <axis xyz="1 0 0" />
        <limit effort="1000" lower="-0.8757" upper="0.8757" velocity="2.0" />
        <mimic joint="finger_joint" multiplier="1" offset="0" />
    </joint>
    <joint name="left_inner_finger_pad_joint" type="fixed">
        <origin rpy="0 0 0" xyz="0 0.0457554015893473 -0.0272203446692936" />
        <parent link="left_inner_finger" />
        <child link="left_inner_finger_pad" />
        <axis xyz="0 0 1" />
    </joint>
    <joint name="right_outer_knuckle_joint" type="revolute">
        <origin rpy="2.29579632679 0 3.14159265359" xyz="0 0.030601 0.054905" />
        <parent link="robotiq_arg2f_base_link" />
        <child link="right_outer_knuckle" />
        <axis xyz="1 0 0" />
        <limit effort="1000" lower="-0.725" upper="0.725" velocity="2.0" />
        <mimic joint="finger_joint" multiplier="-1" offset="0" />
    </joint>
    <joint name="right_outer_finger_joint" type="fixed">
        <origin rpy="0 0 0" xyz="0 0.01821998610742 0.0260018192872234" />
        <parent link="right_outer_knuckle" />
        <child link="right_outer_finger" />
        <axis xyz="1 0 0" />
    </joint>
    <joint name="right_inner_knuckle_joint" type="revolute">
        <origin rpy="2.29579632679 0 -3.14159265359" xyz="0 0.0127 0.06142" />
        <parent link="robotiq_arg2f_base_link" />
        <child link="right_inner_knuckle" />
        <axis xyz="1 0 0" />
        <limit effort="1000" lower="-0.8757" upper="0.8757" velocity="2.0" />
        <mimic joint="finger_joint" multiplier="-1" offset="0" />
    </joint>
    <joint name="right_inner_finger_joint" type="revolute">
        <origin rpy="-0.725 0 0" xyz="0 0.0817554015893473 -0.0282203446692936" />
        <parent link="right_outer_finger" />
        <child link="right_inner_finger" />
        <axis xyz="1 0 0" />
        <limit effort="1000" lower="-0.8757" upper="0.8757" velocity="2.0" />
        <mimic joint="finger_joint" multiplier="1" offset="0" />
    </joint>
    <joint name="right_inner_finger_pad_joint" type="fixed">
        <origin rpy="0 0 0" xyz="0 0.0457554015893473 -0.0272203446692936" />
        <parent link="right_inner_finger" />
        <child link="right_inner_finger_pad" />
        <axis xyz="0 0 1" />
    </joint>
    <transmission name="finger_joint_trans">
        <type>transmission_interface/SimpleTransmission</type>
        <joint name="finger_joint">
            <hardwareInterface>PositionJointInterface</hardwareInterface>
        </joint>
        <actuator name="finger_joint_motor">
            <mechanicalReduction>1</mechanicalReduction>
        </actuator>
    </transmission>
    <gazebo>
        <!-- loading plugin: mimic joints works in gazebo now-->
        <plugin filename="libroboticsgroup_gazebo_mimic_joint_plugin.so" name="mimic_robotiq_140_4">
            <joint>finger_joint</joint>
            <mimicJoint>right_outer_knuckle_joint</mimicJoint>
            <!--<multiplier>-1.0</multiplier>-->
            <!--<offset>0.0</offset>-->
        </plugin>
        <plugin filename="libroboticsgroup_gazebo_mimic_joint_plugin.so" name="mimic_robotiq_140_2">
            <joint>finger_joint</joint>
            <mimicJoint>left_inner_finger_joint</mimicJoint>
            <!--<multiplier>1.0</multiplier>-->
            <!--<offset>0.0</offset>-->
        </plugin>
        <plugin filename="libroboticsgroup_gazebo_mimic_joint_plugin.so" name="mimic_robotiq_140_5">
            <joint>finger_joint</joint>
            <mimicJoint>right_inner_finger_joint</mimicJoint>
            <!--<multiplier>1.0</multiplier>-->
            <!--<offset>0.0</offset>-->
        </plugin>
        <plugin filename="libroboticsgroup_gazebo_mimic_joint_plugin.so" name="mimic_robotiq_140_3">
            <joint>finger_joint</joint>
            <mimicJoint>left_inner_knuckle_joint</mimicJoint>
            <!--<multiplier>-1.0</multiplier>-->
            <!--<offset>0.0</offset>-->
        </plugin>
        <plugin filename="libroboticsgroup_gazebo_mimic_joint_plugin.so" name="mimic_robotiq_140_5">
            <joint>finger_joint</joint>
            <mimicJoint>right_inner_knuckle_joint</mimicJoint>
            <!--<multiplier>-1.0</multiplier>-->
            <!--<offset>0.0</offset>-->
        </plugin>
    </gazebo>
    <link name="upper_chasis">
        <inertial>
            <origin rpy="0 0 0" xyz="0.408010034067037 0.523436425874833 0.310459511796759" />
            <mass value="0.830786236359305" />
            <inertia ixx="0.0113561959346229" ixy="-1.77137015581408E-06" ixz="-1.92392161060582E-12" iyy="0.00307752453202283" iyz="-2.16245929932274E-11" izz="0.00841950781307632" />
        </inertial>
        <visual>
            <origin rpy="0 0 0" xyz="0 0 0" />
            <geometry>
                <mesh filename="package://v5_asm/meshes/upper_chasis.STL" />
            </geometry>
            <material name="">
                <color rgba="0.792156862745098 0.819607843137255 0.933333333333333 1" />
            </material>
        </visual>
        <collision>
            <origin rpy="0 0 0" xyz="0 0 0" />
            <geometry>
                <mesh filename="package://v5_asm/meshes/upper_chasis.STL" />
            </geometry>
        </collision>
    </link>
    <joint name="upper_chasis" type="fixed">
        <origin rpy="1.5708 0 1.5708" xyz="-0.07828 -0.90265 0.78248" />
        <parent link="base_link_main" />
        <child link="upper_chasis" />
        <axis xyz="0 0 0" />
    </joint>
    <link name="kinect">
        <inertial>
            <origin rpy="0 0 0" xyz="2.85546254141789E-06 0.00442617876381557 -0.0296652165432638" />
            <mass value="2.43875456249446" />
            <inertia ixx="0.00366777685200428" ixy="3.65666914100067E-08" ixz="-4.13408382742863E-07" iyy="0.0053508686708892" iyz="0.000216031980389351" izz="0.00205613161528836" />
        </inertial>
        <visual>
            <origin rpy="0 0 0" xyz="0 0 0" />
            <geometry>
                <mesh filename="package://v5_asm/meshes/kinect.dae" />
            </geometry>
            <material name="">
                <color rgba="0.941176470588235 0.941176470588235 0.941176470588235 1" />
            </material>
        </visual>
        <collision>
            <origin rpy="0 0 0" xyz="0 0 0" />
            <geometry>
                <mesh filename="package://v5_asm/meshes/kinect.dae" />
            </geometry>
        </collision>
    </link>
    <joint name="kinect" type="fixed">
        <!-- .31779 -->
        <origin rpy="-1.57079632679 -1.5708 0" xyz="0.378055 0.80334 0.30488" />
        <parent link="upper_chasis" />
        <child link="kinect" />
        <axis xyz="0 0 0" />
    </joint>
    <link name="lidar">
        <inertial>
            <origin rpy="0 0 0" xyz="0.000294783332731696 0.0357745252112349 -2.58234201516716E-06" />
            <mass value="0.585082164914895" />
            <inertia ixx="0.00062906696678346" ixy="-6.8476888066688E-08" ixz="-1.14106053435051E-10" iyy="0.000749251783736662" iyz="-5.004876230364E-08" izz="0.000630263932043022" />
        </inertial>
        <visual>
            <origin rpy="0 0 0" xyz="0 0 0" />
            <geometry>
                <mesh filename="package://v5_asm/meshes/lidar.dae" />
            </geometry>
            <material name="">
                <color rgba="0.792156862745098 0.819607843137255 0.933333333333333 1" />
            </material>
        </visual>
        <collision>
            <origin rpy="0 0 0" xyz="0 0 0" />
            <geometry>
                <mesh filename="package://v5_asm/meshes/lidar.dae" />
            </geometry>
        </collision>
    </link>
    <joint name="lidar" type="fixed">
        <origin rpy="1.57079632679 0 0" xyz="0.40469 0.763 0.30488" />
        <parent link="upper_chasis" />
        <child link="lidar" />
        <axis xyz="0 0 0" />
    </joint>
    <link name="monitor">
        <inertial>
            <origin rpy="0 0 0" xyz="-9.44272438019311E-13 0.0100274135784167 1.28586030712086E-12" />
            <mass value="1.77239075139848" />
            <inertia ixx="0.0081743729118215" ixy="-2.82200542311203E-12" ixz="4.5362584792376E-17" iyy="0.0290517648183889" iyz="-6.23620652586998E-17" izz="0.0209962115185463" />
        </inertial>
        <visual>
            <origin rpy="0 0 0" xyz="0 0 0" />
            <geometry>
                <mesh filename="package://v5_asm/meshes/monitor.dae" />
            </geometry>
            <material name="">
                <color rgba="0.647058823529412 0.619607843137255 0.6 1" />
            </material>
        </visual>
        <collision>
            <origin rpy="0 0 0" xyz="0 0 0" />
            <geometry>
                <mesh filename="package://v5_asm/meshes/monitor.dae" />
            </geometry>
        </collision>
    </link>
    <joint name="monitor" type="fixed">
        <origin rpy="0 1.5708 0" xyz="0.4177 0.55518 0.3106" />
        <parent link="upper_chasis" />
        <child link="monitor" />
        <axis xyz="0 0 0" />
    </joint>
    <link name="hokuyo">
        <inertial>
            <origin rpy="0 0 0" xyz="0.133584074211728 0.202324368680826 0.204105336507967" />
            <mass value="0.652167585839582" />
            <inertia ixx="0.00157050335763022" ixy="1.74853977399192E-06" ixz="3.70456316395289E-08" iyy="0.00157786080287871" iyz="-1.22184572203833E-07" izz="0.000194017970807751" />
        </inertial>
        <visual>
            <origin rpy="0 0 0" xyz="0 0 0" />
            <geometry>
                <mesh filename="package://v5_asm/meshes/hokuyo.dae" />
            </geometry>
            <material name="">
                <color rgba="0.752941176470588 0.752941176470588 0.752941176470588 1" />
            </material>
        </visual>
        <collision>
            <origin rpy="0 0 0" xyz="0 0 0" />
            <geometry>
                <mesh filename="package://v5_asm/meshes/hokuyo.dae" />
            </geometry>
        </collision>
    </link>
    <joint name="base_to_hokuyo" type="fixed">
        <origin rpy="0 3.14159265 1.5707963267949" xyz="0.02746682844 -0.977022583965 0.73431985122" />
        <parent link="base_link_main" />
        <child link="hokuyo" />
        <axis xyz="0 0 0" />
    </joint>
    <transmission name="trans_shoulder_pan_joint">
        <type>transmission_interface/SimpleTransmission</type>
        <joint name="shoulder_pan_joint">
            <hardwareInterface>hardware_interface/EffortJointInterface</hardwareInterface>
        </joint>
        <actuator name="shoulder_pan_joint_motor">
            <hardwareInterface>hardware_interface/EffortJointInterface</hardwareInterface>
            <mechanicalReduction>1</mechanicalReduction>
        </actuator>
    </transmission>
    <transmission name="trans_shoulder_lift_joint">
        <type>transmission_interface/SimpleTransmission</type>
        <joint name="shoulder_lift_joint">
            <hardwareInterface>hardware_interface/EffortJointInterface</hardwareInterface>
        </joint>
        <actuator name="shoulder_lift_joint_motor">
            <hardwareInterface>hardware_interface/EffortJointInterface</hardwareInterface>
            <mechanicalReduction>1</mechanicalReduction>
        </actuator>
    </transmission>
    <transmission name="trans_elbow_joint">
        <type>transmission_interface/SimpleTransmission</type>
        <joint name="elbow_joint">
            <hardwareInterface>hardware_interface/EffortJointInterface</hardwareInterface>
        </joint>
        <actuator name="elbow_joint_motor">
            <hardwareInterface>hardware_interface/EffortJointInterface</hardwareInterface>
            <mechanicalReduction>1</mechanicalReduction>
        </actuator>
    </transmission>
    <transmission name="trans_wrist_1_joint">
        <type>transmission_interface/SimpleTransmission</type>
        <joint name="wrist_1_joint">
            <hardwareInterface>hardware_interface/EffortJointInterface</hardwareInterface>
        </joint>
        <actuator name="wrist_1_joint_motor">
            <hardwareInterface>hardware_interface/EffortJointInterface</hardwareInterface>
            <mechanicalReduction>1</mechanicalReduction>
        </actuator>
    </transmission>
    <transmission name="trans_wrist_2_joint">
        <type>transmission_interface/SimpleTransmission</type>
        <joint name="wrist_2_joint">
            <hardwareInterface>hardware_interface/EffortJointInterface</hardwareInterface>
        </joint>
        <actuator name="wrist_2_joint_motor">
            <hardwareInterface>hardware_interface/EffortJointInterface</hardwareInterface>
            <mechanicalReduction>1</mechanicalReduction>
        </actuator>
    </transmission>
    <transmission name="trans_wrist_3_joint">
        <type>transmission_interface/SimpleTransmission</type>
        <joint name="wrist_3_joint">
            <hardwareInterface>hardware_interface/EffortJointInterface</hardwareInterface>
        </joint>
        <actuator name="wrist_3_joint_motor">
            <hardwareInterface>hardware_interface/EffortJointInterface</hardwareInterface>
            <mechanicalReduction>1</mechanicalReduction>
        </actuator>
    </transmission>
    <transmission name="trans_left_wheel">
        <type>transmission_interface/SimpleTransmission</type>
        <joint name="left_wheel">
            <hardwareInterface>hardware_interface/EffortJointInterface</hardwareInterface>
        </joint>
        <actuator name="left_wheel_motor">
            <hardwareInterface>hardware_interface/EffortJointInterface</hardwareInterface>
            <mechanicalReduction>1</mechanicalReduction>
        </actuator>
    </transmission>
    <transmission name="trans_right_wheel">
        <type>transmission_interface/SimpleTransmission</type>
        <joint name="right_wheel">
            <hardwareInterface>hardware_interface/EffortJointInterface</hardwareInterface>
        </joint>
        <actuator name="right_wheel_motor">
            <hardwareInterface>hardware_interface/EffortJointInterface</hardwareInterface>
            <mechanicalReduction>1</mechanicalReduction>
        </actuator>
    </transmission>
    <transmission name="trans_rear_caster_swivel">
        <type>transmission_interface/SimpleTransmission</type>
        <joint name="rear_caster_swivel">
            <hardwareInterface>hardware_interface/EffortJointInterface</hardwareInterface>
        </joint>
        <actuator name="rear_caster_swivel_motor">
            <hardwareInterface>hardware_interface/EffortJointInterface</hardwareInterface>
            <mechanicalReduction>1</mechanicalReduction>
        </actuator>
    </transmission>
    <transmission name="trans_rear_caster_wheel">
        <type>transmission_interface/SimpleTransmission</type>
        <joint name="rear_caster_wheel">
            <hardwareInterface>hardware_interface/EffortJointInterface</hardwareInterface>
        </joint>
        <actuator name="rear_caster_wheel_motor">
            <hardwareInterface>hardware_interface/EffortJointInterface</hardwareInterface>
            <mechanicalReduction>1</mechanicalReduction>
        </actuator>
    </transmission>
    <transmission name="trans_front_caster_swivel">
        <type>transmission_interface/SimpleTransmission</type>
        <joint name="front_caster_swivel">
            <hardwareInterface>hardware_interface/EffortJointInterface</hardwareInterface>
        </joint>
        <actuator name="front_caster_swivel_motor">
            <hardwareInterface>hardware_interface/EffortJointInterface</hardwareInterface>
            <mechanicalReduction>1</mechanicalReduction>
        </actuator>
    </transmission>
    <transmission name="trans_front_caster_wheel">
        <type>transmission_interface/SimpleTransmission</type>
        <joint name="front_caster_wheel">
            <hardwareInterface>hardware_interface/EffortJointInterface</hardwareInterface>
        </joint>
        <actuator name="front_caster_wheel_motor">
            <hardwareInterface>hardware_interface/EffortJointInterface</hardwareInterface>
            <mechanicalReduction>1</mechanicalReduction>
        </actuator>
    </transmission>
    <transmission name="trans_finger_joint">
        <type>transmission_interface/SimpleTransmission</type>
        <joint name="finger_joint">
            <hardwareInterface>hardware_interface/EffortJointInterface</hardwareInterface>
        </joint>
        <actuator name="finger_joint_motor">
            <hardwareInterface>hardware_interface/EffortJointInterface</hardwareInterface>
            <mechanicalReduction>1</mechanicalReduction>
        </actuator>
    </transmission>
    <transmission name="trans_left_inner_knuckle_joint">
        <type>transmission_interface/SimpleTransmission</type>
        <joint name="left_inner_knuckle_joint">
            <hardwareInterface>hardware_interface/EffortJointInterface</hardwareInterface>
        </joint>
        <actuator name="left_inner_knuckle_joint_motor">
            <hardwareInterface>hardware_interface/EffortJointInterface</hardwareInterface>
            <mechanicalReduction>1</mechanicalReduction>
        </actuator>
    </transmission>
    <transmission name="trans_left_inner_finger_joint">
        <type>transmission_interface/SimpleTransmission</type>
        <joint name="left_inner_finger_joint">
            <hardwareInterface>hardware_interface/EffortJointInterface</hardwareInterface>
        </joint>
        <actuator name="left_inner_finger_joint_motor">
            <hardwareInterface>hardware_interface/EffortJointInterface</hardwareInterface>
            <mechanicalReduction>1</mechanicalReduction>
        </actuator>
    </transmission>
    <transmission name="trans_right_outer_knuckle_joint">
        <type>transmission_interface/SimpleTransmission</type>
        <joint name="right_outer_knuckle_joint">
            <hardwareInterface>hardware_interface/EffortJointInterface</hardwareInterface>
        </joint>
        <actuator name="right_outer_knuckle_joint_motor">
            <hardwareInterface>hardware_interface/EffortJointInterface</hardwareInterface>
            <mechanicalReduction>1</mechanicalReduction>
        </actuator>
    </transmission>
    <transmission name="trans_right_inner_knuckle_joint">
        <type>transmission_interface/SimpleTransmission</type>
        <joint name="right_inner_knuckle_joint">
            <hardwareInterface>hardware_interface/EffortJointInterface</hardwareInterface>
        </joint>
        <actuator name="right_inner_knuckle_joint_motor">
            <hardwareInterface>hardware_interface/EffortJointInterface</hardwareInterface>
            <mechanicalReduction>1</mechanicalReduction>
        </actuator>
    </transmission>
    <transmission name="trans_right_inner_finger_joint">
        <type>transmission_interface/SimpleTransmission</type>
        <joint name="right_inner_finger_joint">
            <hardwareInterface>hardware_interface/EffortJointInterface</hardwareInterface>
        </joint>
        <actuator name="right_inner_finger_joint_motor">
            <hardwareInterface>hardware_interface/EffortJointInterface</hardwareInterface>
            <mechanicalReduction>1</mechanicalReduction>
        </actuator>
    </transmission>
    <gazebo>
        <plugin name="gazebo_ros_control" filename="libgazebo_ros_control.so">
            <robotNamespace>/</robotNamespace>
        </plugin>
    </gazebo>
</robot>
